Workbook

Sheet Como usar
B2: Raio-X financeiro em 15 minutos
B3: Finanças que Curam · Grupo FQC · Comunidade Manada · Por Aline Seabra
B5: Antes de mudar qualquer coisa no seu dinheiro, você precisa enxergar onde ele está.
B7: Como preencher
B8: 1. Separe o extrato e a fatura do cartão do último mês.
B9: 2. Na aba Raio-X, preencha só as células amarelas. Os valores em azul são um exemplo: troque pelos seus.
B10: 3. Linhas que não fazem sentido para você podem ficar em branco ou com zero.
B11: 4. Na coluna Emoção dos gastos variáveis, escolha o que você sentia na hora da compra.
B12: 5. Abra a aba Resultado: os seus 4 indicadores e o saldo do mês aparecem sozinhos.
B14: Legenda
B15: Célula amarela = você preenche. Texto azul = valor de exemplo. Texto preto = cálculo automático, não apague.
B17: Combinado da Manada
... B21: Conteúdo educativo. Não é recomendação de investimento.

Sheet Raio-X
B2: Raio-X financeiro
B3: Mês de referência | C3: Outubro/2026
B5: 1. Quanto entrou no mês
B6: Valores líquidos, que caíram na conta.
B7: Fonte de renda | C7: Valor (R$)
B8: Salário líquido | C8: 7900
B9: Renda extra / freelas | C9: 800
B10: Pensão, aluguel recebido, outros | C10: 0
B11: Total de entradas | C11: =SUM(C8:C10) -> 8700
B14: 2. Gastos fixos
B15: Contas que se repetem todo mês com valor parecido.
B16: Despesa | C16: Valor (R$)
B17: Aluguel / financiamento da casa | C17: 1800
B18: Condomínio e IPTU (mensal) | C18: 450
B19: Luz, água e gás | C19: 320
B20: Internet e celular | C20: 180
B21: Escola / faculdade | C21: 900
B22: Plano de saúde | C22: 650
B23: Transporte fixo (parcela do carro, passe) | C23: 0
B24: Assinaturas (streaming, apps, academia) | C24: 160
B25: Outros fixos | C25: 0
B26: Total de gastos fixos | C26: =SUM(C17:C25) -> 4460
B29: 3. Gastos variáveis
B30: Mudam de um mês para o outro. Marque a emoção que mais aparecia nessas compras.
B31: Despesa | C31: Valor (R$) | D31: Emoção
B32: Mercado e feira | C32: 1200 | D32: Necessidade
B33: Delivery e restaurantes | C33: 520 | D33: Recompensa
B34: Combustível, app de transporte | C34: 350 | D34: Necessidade
B35: Lazer e passeios | C35: 300 | D35: Alegria
B36: Roupas, beleza e compras pessoais | C36: 380 | D36: Estresse
B37: Farmácia | C37: 150 | D37: Necessidade
B38: Presentes | C38: 120 | D38: Pressão social
B39: Outros variáveis | C39: 90 | D39: Tédio
B40: Total de gastos variáveis | C40: =SUM(C32:C39) -> 3110
B43: 4. Dívidas
B44: Cartão parcelado, empréstimo, financiamento, cheque especial. Juros pelo contrato ou pelo app do banco.
B45: Credor / tipo | C45: Saldo devedor (R$) | D45: Juros (% ao mês) | E45: Parcela (R$) | F45: Parcelas restantes | G45: Juros considerados
B46: Cartão de crédito parcelado | C46: 2400 | D46: 0 | E46: 400 | F46: 6 | G46: =IF(C46>0,D46,0) -> 0
B47: Empréstimo pessoal | C47: 6000 | D47: 0.035 | E47: 520 | F47: 14 | G47: =IF(C47>0,D47,0) -> 0.035
B48: Cheque especial | C48: 0 | D48: 0.08 | E48: 0 | F48: 0 | G48: =IF(C48>0,D48,0) -> 0
...

Sheet Resultado
B2: Seu resultado
B3: ='Raio-X'!C3 -> Outubro/2026
B5: O mês em números
B6: Entradas | C6: ='Raio-X'!C11 -> 8700
B7: Gastos fixos | C7: ='Raio-X'!C26 -> 4460
B8: Gastos variáveis | C8: ='Raio-X'!C40 -> 3110
B9: Parcelas de dívidas | C9: ='Raio-X'!E50 -> 920
B10: Sobra (ou falta) do mês | C10: =C6-C7-C8-C9 -> 210
B11: Saldo total das dívidas | C11: ='Raio-X'!C50 -> 8400
B12: Reserva de emergência | C12: ='Raio-X'!C59 -> 4000
B14: Seus 4 indicadores
B15: Indicador | C15: Seu número | D15: Situação | E15: Referência
B16: Taxa de poupança | C16: =IF(C6>0,MAX(C10,0)/C6,0) -> 0.024137931 | D16: =IF(C16>=$C$27,"Saudável",IF(C16>0,"Atenção","Alerta")) -> Atenção | E16: Quanto sobra ÷ entradas. Meta inicial: 10% ou mais.
B17: Índice de endividamento | C17: =IF(C6>0,C9/C6,0) -> 0.10574713 | D17: =IF(C17<=$C$28,"Saudável",IF(C17<=$C$29,"Atenção","Alerta")) -> Saudável | E17: Parcelas de dívidas ÷ entradas. Ideal: até 30%.
B18: Meses de reserva | C18: =IF(C7>0,C12/C7,0) -> 0.89686099 | D18: =IF(C18>=$C$31,"Saudável",IF(C18>=$C$30,"Atenção","Alerta")) -> Alerta | E18: Reserva ÷ gastos fixos. Meta: de 3 a 6 meses (6 a 12 para renda variável).
B19: Peso do custo fixo | C19: =IF(C6>0,C7/C6,0) -> 0.51264368 | D19: =IF(C19<=$C$32,"Saudável",IF(C19<=$C$33,"Atenção","Alerta")) -> Atenção | E19: Gastos fixos ÷ entradas. Quanto menor, mais liberdade.
B21: Pistas para começar
B22: Dívida com o maior juro (avalanche) | C22: =IF(MAX('Raio-X'!G46:G49)>0,INDEX('Raio-X'!B46:B49,MATCH(MAX('Raio-X'!G46:G49),'Raio-X'!G46:G49,0)),"Sem dívidas com juros") -> Empréstimo pessoal
B23: Gasto variável mais alto | C23: =INDEX('Raio-X'!B32:B39,MATCH(MAX('Raio-X'!C32:C39),'Raio-X'!C32:C39,0)) -> Mercado e feira
B24: Valor gasto por recompensa, tédio ou estresse | C24: =SUMIF('Raio-X'!D32:D39,"Recompensa",'Raio-X'!C32:C39)+SUMIF('Raio-X'!D32:D39,"Tédio",'Raio-X'!C32:C39)+SUMIF('Raio-X'!D32:D39,"Estresse",'Raio-X'!C32:C39) -> 990
B26: Referências usadas nos semáforos (pode ajustar)
B27: Taxa de poupança saudável a partir de | C27: 0.1
B28: Endividamento saudável até | C28: 0.3
B29: Endividamento em atenção até | C29: 0.4
B30: Reserva em atenção a partir de (meses) | C30: 3
B31: Reserva saudável a partir de (meses) | C31: 6
B32: Custo fixo saudável até | C32: 0.5
B33: Custo fixo em atenção até | C33: 0.65
B34: Referências educativas da Manada, baseadas em práticas comuns de planejamento financeiro pessoal.
