Workbook

Sheet Como usar
B2: Avalanche ou bola de neve?
B3: Finanças que Curam · Grupo FQC · Comunidade Manada · Por Aline Seabra
B5: A técnica diz avalanche. A emoção diz bola de neve. Aqui você vê os dois caminhos lado a lado e escolhe o que vai conseguir manter.
B7: Como preencher
B8: 1. Na aba Dívidas, liste até 10 dívidas: saldo de hoje, juros ao mês e a parcela mínima que você paga.
B9: 2. Informe quanto você consegue pagar a mais por mês, além das parcelas mínimas (o valor extra).
B10: 3. A aba Resultado mostra, para cada método, a ordem de pagamento, em quantos meses tudo termina e quanto você paga de juros.
B11: 4. Regra do jogo: quando uma dívida acaba, a parcela dela não volta para o orçamento. Ela passa a reforçar a próxima da fila. É isso que faz a bola crescer.
B12: Avalanche: paga primeiro a dívida com o MAIOR juro. É a mais barata em números.
B13: Bola de neve: paga primeiro a dívida com o MENOR saldo. Ela some rápido e dá motivação para continuar.
B15: Legenda
B16: Célula amarela = você preenche. Texto azul = valor de exemplo. Texto preto = cálculo automático, não apague.
... B21: Conteúdo educativo. Não é recomendação de investimento.

Sheet Dívidas
B2: Suas dívidas
B4: Mês em que você começa o plano | C4: 46327
B5: Valor extra por mês, além das mínimas (R$) | C5: 400
G6: Chaves de ordenação (não apague)
B7: Credor / tipo de dívida | C7: Saldo hoje (R$) | D7: Juros (% ao mês) | E7: Parcela mínima (R$)
B8: Cartão de crédito (rotativo) | C8: 3000 | D8: 0.12 | E8: 300 | G8: =IF(N(C8)>0,N(D8)+ROW()/1000000000,-1) -> 0.12000001 | H8: =IF(N(C8)>0,N(C8)+ROW()/1000000,1000000000000) -> 3000
B9: Empréstimo pessoal | C9: 8000 | D9: 0.035 | E9: 450 | G9: =IF(N(C9)>0,N(D9)+ROW()/1000000000,-1) -> 0.035000009 | H9: =IF(N(C9)>0,N(C9)+ROW()/1000000,1000000000000) -> 8000
B10: Cheque especial | C10: 1200 | D10: 0.08 | E10: 150 | G10: =IF(N(C10)>0,N(D10)+ROW()/1000000000,-1) -> 0.08000001 | H10: =IF(N(C10)>0,N(C10)+ROW()/1000000,1000000000000) -> 1200
B11: Compra parcelada na loja | C11: 900 | D11: 0 | E11: 150 | G11: =IF(N(C11)>0,N(D11)+ROW()/1000000000,-1) -> 1.1e-08 | H11: =IF(N(C11)>0,N(C11)+ROW()/1000000,1000000000000) -> 900.00001
G12: =IF(N(C12)>0,N(D12)+ROW()/1000000000,-1) -> -1 | H12: =IF(N(C12)>0,N(C12)+ROW()/1000000,1000000000000) -> 1000000000000
G13: =IF(N(C13)>0,N(D13)+ROW()/1000000000,-1) -> -1 | H13: =IF(N(C13)>0,N(C13)+ROW()/1000000,1000000000000) -> 1000000000000
G14: =IF(N(C14)>0,N(D14)+ROW()/1000000000,-1) -> -1 | H14: =IF(N(C14)>0,N(C14)+ROW()/1000000,1000000000000) -> 1000000000000
G15: =IF(N(C15)>0,N(D15)+ROW()/1000000000,-1) -> -1 | H15: =IF(N(C15)>0,N(C15)+ROW()/1000000,1000000000000) -> 1000000000000
G16: =IF(N(C16)>0,N(D16)+ROW()/1000000000,-1) -> -1 | H16: =IF(N(C16)>0,N(C16)+ROW()/1000000,1000000000000) -> 1000000000000
G17: =IF(N(C17)>0,N(D17)+ROW()/1000000000,-1) -> -1 | H17: =IF(N(C17)>0,N(C17)+ROW()/1000000,1000000000000) -> 1000000000000
B18: Totais | C18: =SUM(C8:C17) -> 13100 | E18: =SUM(E8:E17) -> 1050
B20: Orçamento mensal para dívidas (mínimas + extra) | C20: =E18+C5 -> 1450
B21: Juros do primeiro mês (todas as dívidas) | C21: =SUMPRODUCT(C8:C17,D8:D17) -> 736
B23: Dica: o juro do cartão rotativo e do cheque especial costuma passar de 8% ao mês. Confira no app do banco ou na fatura (CET).

Sheet Resultado
B2: Avalanche × Bola de neve
B3: Mesmo orçamento, duas ordens diferentes.
C5: Avalanche | D5: Bola de neve
B6: Primeira dívida a atacar | C6: =Ordem!C6 -> Cartão de crédito (rotativo) | D6: =Ordem!I6 -> Compra parcelada na loja
B7: Segunda | C7: =Ordem!C7 -> Cheque especial | D7: =Ordem!I7 -> Cheque especial
B8: Terceira | C8: =Ordem!C8 -> Empréstimo pessoal | D8: =Ordem!I8 -> Cartão de crédito (rotativo)
B9: Meses até ficar sem dívidas | C9: =IF(Dívidas!C18<=0,0,IF(COUNTIF('Sim Avalanche'!AQ5:AQ124,">0.01")>=120,"Mais de 10 anos",COUNTIF('Sim Avalanche'!AQ5:AQ124,">0.01")+1)) -> 13 | D9: =IF(Dívidas!C18<=0,0,IF(COUNTIF('Sim Bola de neve'!AQ5:AQ124,">0.01")>=120,"Mais de 10 anos",COUNTIF('Sim Bola de neve'!AQ5:AQ124,">0.01")+1)) -> 13
B10: Livre das dívidas em | C10: =IF(ISNUMBER(C9),EDATE(Dívidas!$C$4,C9-1),"-") -> 46692 | D10: =IF(ISNUMBER(D9),EDATE(Dívidas!$C$4,D9-1),"-") -> 46692
B11: Total de juros pagos no caminho | C11: =SUM('Sim Avalanche'!AR5:AR124)+'Sim Avalanche'!AQ124-Dívidas!C18 -> 4637.5231 | D11: =SUM('Sim Bola de neve'!AR5:AR124)+'Sim Bola de neve'!AQ124-Dívidas!C18 -> 5328.3728
B12: Meses até a primeira vitória (1ª dívida quitada) | C12: =IFERROR(MATCH(0,'Sim Avalanche'!F5:F124,0),"-") -> 7 | D12: =IFERROR(MATCH(0,'Sim Bola de neve'!F5:F124,0),"-") -> 2
B14: Economia de juros da avalanche | C14: =D11-C11 -> 690.84973
B16: Leitura da Manada
B17: =IF(Dívidas!C21>=Dívidas!C20,"Atenção: o orçamento não cobre nem os juros do mês. Antes de escolher um método, procure renegociar a dívida mais cara ou aumentar o valor extra.",IF(D11-C11>200,"A avalanche economiza "&"R$ "&FIXED(D11-C11,0)&" em juros. Se você precisa de vitórias rápidas para não desistir, a bola de neve quita a primeira dívida em "&D12&" meses. Escolha o que você vai conseguir manter.","Os dois métodos ficam parecidos no seu caso. Vá de bola de neve: as vitórias rápidas ajudam a não desistir.")) -> A avalanche economiza R$ 691 em juros. Se você precisa de vitórias rápidas para não desistir, a bola de neve quita a primeira dívida em 2 meses. Escolha o que você vai conseguir manter.
B22: Primeiros 60 meses

Sheet Ordem
B2: Fila de pagamento de cada método
B4: Avalanche · maior juro primeiro | H4: Bola de neve · menor saldo primeiro
B5: Fila | C5: Credor | D5: Saldo (R$) | E5: Juros | F5: Mínima (R$) | H5: Fila | I5: Credor | J5: Saldo (R$) | K5: Juros | L5: Mínima (R$)
B6: 1 | C6: =IF(N(INDEX(Dívidas!$C$8:$C$17,MATCH(LARGE(Dívidas!$G$8:$G$17,1),Dívidas!$G$8:$G$17,0)))>0,INDEX(Dívidas!$B$8:$B$17,MATCH(LARGE(Dívidas!$G$8:$G$17,1),Dívidas!$G$8:$G$17,0)),"") -> Cartão de crédito (rotativo) | D6: =IF(N(INDEX(Dívidas!$C$8:$C$17,MATCH(LARGE(Dívidas!$G$8:$G$17,1),Dívidas!$G$8:$G$17,0)))>0,N(INDEX(Dívidas!$C$8:$C$17,MATCH(LARGE(Dívidas!$G$8:$G$17,1),Dívidas!$G$8:$G$17,0))),0) -> 3000 | E6: =IF(N(INDEX(Dívidas!$C$8:$C$17,MATCH(LARGE(Dívidas!$G$8:$G$17,1),Dívidas!$G$8:$G$17,0)))>0,N(INDEX(Dívidas!$D$8:$D$17,MATCH(LARGE(Dívidas!$G$8:$G$17,1),Dívidas!$G$8:$G$17,0))),0) -> 0.12 | F6: =IF(N(INDEX(Dívidas!$C$8:$C$17,MATCH(LARGE(Dívidas!$G$8:$G$17,1),Dívidas!$G$8:$G$17,0)))>0,N(INDEX(Dívidas!$E$8:$E$17,MATCH(LARGE(Dívidas!$G$8:$G$17,1),Dívidas!$G$8:$G$17,0))),0) -> 300 | H6: 1 | I6: =IF(N(INDEX(Dívidas!$C$8:$C$17,MATCH(SMALL(Dívidas!$H$8:$H$17,1),Dívidas!$H$8:$H$17,0)))>0,INDEX(Dívidas!$B$8:$B$17,MATCH(SMALL(Dívidas!$H$8:$H$17,1),Dívidas!$H$8:$H$17,0)),"") -> Compra parcelada na loja | J6: =IF(N(INDEX(Dívidas!$C$8:$C$17,MATCH(SMALL(Dívidas!$H$8:$H$17,1),Dívidas!$H$8:$H$17,0)))>0,N(INDEX(Dívidas!$C$8:$C$17,MATCH(SMALL(Dívidas!$H$8:$H$17,1),Dívidas!$H$8:$H$17,0))),0) -> 900 | K6: =IF(N(INDEX(Dívidas!$C$8:$C$17,MATCH(SMALL(Dívidas!$H$8:$H$17,1),Dívidas!$H$8:$H$17,0)))>0,N(INDEX(Dívidas!$D$8:$D$17,MATCH(SMALL(Dívidas!$H$8:$H$17,1),Dívidas!$H$8:$H$17,0))),0) -> 0 | L6: =IF(N(INDEX(Dívidas!$C$8:$C$17,MATCH(SMALL(Dívidas!$H$8:$H$17,1),Dívidas!$H$8:$H$17,0)))>0,N(INDEX(Dívidas!$E$8:$E$17,MATCH(SMALL(Dívidas!$H$8:$H$17,1),Dívidas!$H$8:$H$17,0))),0) -> 150
B7: 2 | C7: =IF(N(INDEX(Dívidas!$C$8:$C$17,MATCH(LARGE(Dívidas!$G$8:$G$17,2),Dívidas!$G$8:$G$17,0)))>0,INDEX(Dívidas!$B$8:$B$17,MATCH(LARGE(Dívidas!$G$8:$G$17,2),Dívidas!$G$8:$G$17,0)),"") -> Cheque especial | D7: =IF(N(INDEX(Dívidas!$C$8:$C$17,MATCH(LARGE(Dívidas!$G$8:$G$17,2),Dívidas!$G$8:$G$17,0)))>0,N(INDEX(Dívidas!$C$8:$C$17,MATCH(LARGE(Dívidas!$G$8:$G$17,2),Dívidas!$G$8:$G$17,0))),0) -> 1200 | E7: =IF(N(INDEX(Dívidas!$C$8:$C$17,MATCH(LARGE(Dívidas!$G$8:$G$17,2),Dívidas!$G$8:$G$17,0)))>0,N(INDEX(Dívidas!$D$8:$D$17,MATCH(LARGE(Dívidas!$G$8:$G$17,2),Dívidas!$G$8:$G$17,0))),0) -> 0.08 | F7: =IF(N(INDEX(Dívidas!$C$8:$C$17,MATCH(LARGE(Dívidas!$G$8:$G$17,2),Dívidas!$G$8:$G$17,0)))>0,N(INDEX(Dívidas!$E$8:$E$17,MATCH(LARGE(Dívidas!$G$8:$G$17,2),Dívidas!$G$8:$G$17,0))),0) -> 150 | H7: 2 | I7: =IF(N(INDEX(Dívidas!$C$8:$C$17,MATCH(SMALL(Dívidas!$H$8:$H$17,2),Dívidas!$H$8:$H$17,0)))>0,INDEX(Dívidas!$B$8:$B$17,MATCH(SMALL(Dívidas!$H$8:$H$17,2),Dívidas!$H$8:$H$17,0)),"") -> Cheque especial | J7: =IF(N(INDEX(Dívidas!$C$8:$C$17,MATCH(SMALL(Dívidas!$H$8:$H$17,2),Dívidas!$H$8:$H$17,0)))>0,N(INDEX(Dívidas!$C$8:$C$17,MATCH(SMALL(Dívidas!$H$8:$H$17,2),Dívidas!$H$8:$H$17,0))),0) -> 1200 | K7: =IF(N(INDEX(Dívidas!$C$8:$C$17,MATCH(SMALL(Dívidas!$H$8:$H$17,2),Dívidas!$H$8:$H$17,0)))>0,N(INDEX(Dívidas!$D$8:$D$17,MATCH(SMALL(Dívidas!$H$8:$H$17,2),Dívidas!$H$8:$H$17,0))),0) -> 0.08 | L7: =IF(N(INDEX(Dívidas!$C$8:$C$17,MATCH(SMALL(Dívidas!$H$8:$H$17,2),Dívidas!$H$8:$H$17,0)))>0,N(INDEX(Dívidas!$E$8:$E$17,MATCH(SMALL(Dívidas!$H$8:$H$17,2),Dívidas!$H$8:$H$17,0))),0) -> 150
B8: 3 | C8: =IF(N(INDEX(Dívidas!$C$8:$C$17,MATCH(LARGE(Dívidas!$G$8:$G$17,3),Dívidas!$G$8:$G$17,0)))>0,INDEX(Dívidas!$B$8:$B$17,MATCH(LARGE(Dívidas!$G$8:$G$17,3),Dívidas!$G$8:$G$17,0)),"") -> Empréstimo pessoal | D8: =IF(N(INDEX(Dívidas!$C$8:$C$17,MATCH(LARGE(Dívidas!$G$8:$G$17,3),Dívidas!$G$8:$G$17,0)))>0,N(INDEX(Dívidas!$C$8:$C$17,MATCH(LARGE(Dívidas!$G$8:$G$17,3),Dívidas!$G$8:$G$17,0))),0) -> 8000 | E8: =IF(N(INDEX(Dívidas!$C$8:$C$17,MATCH(LARGE(Dívidas!$G$8:$G$17,3),Dívidas!$G$8:$G$17,0)))>0,N(INDEX(Dívidas!$D$8:$D$17,MATCH(LARGE(Dívidas!$G$8:$G$17,3),Dívidas!$G$8:$G$17,0))),0) -> 0.035 | F8: =IF(N(INDEX(Dívidas!$C$8:$C$17,MATCH(LARGE(Dívidas!$G$8:$G$17,3),Dívidas!$G$8:$G$17,0)))>0,N(INDEX(Dívidas!$E$8:$E$17,MATCH(LARGE(Dívidas!$G$8:$G$17,3),Dívidas!$G$8:$G$17,0))),0) -> 450 | H8: 3 | I8: =IF(N(INDEX(Dívidas!$C$8:$C$17,MATCH(SMALL(Dívidas!$H$8:$H$17,3),Dívidas!$H$8:$H$17,0)))>0,INDEX(Dívidas!$B$8:$B$17,MATCH(SMALL(Dívidas!$H$8:$H$17,3),Dívidas!$H$8:$H$17,0)),"") -> Cartão de crédito (rotativo) | J8: =IF(N(INDEX(Dívidas!$C$8:$C$17,MATCH(SMALL(Dívidas!$H$8:$H$17,3),Dívidas!$H$8:$H$17,0)))>0,N(INDEX(Dívidas!$C$8:$C$17,MATCH(SMALL(Dívidas!$H$8:$H$17,3),Dívidas!$H$8:$H$17,0))),0) -> 3000 | K8: =IF(N(INDEX(Dívidas!$C$8:$C$17,MATCH(SMALL(Dívidas!$H$8:$H$17,3),Dívidas!$H$8:$H$17,0)))>0,N(INDEX(Dívidas!$D$8:$D$17,MATCH(SMALL(Dívidas!$H$8:$H$17,3),Dívidas!$H$8:$H$17,0))),0) -> 0.12 | L8: =IF(N(INDEX(Dívidas!$C$8:$C$17,MATCH(SMALL(Dívidas!$H$8:$H$17,3),Dívidas!$H$8:$H$17,0)))>0,N(INDEX(Dívidas!$E$8:$E$17,MATCH(SMALL(Dívidas!$H$8:$H$17,3),Dívidas!$H$8:$H$17,0))),0) -> 300
B9: 4 | C9: =IF(N(INDEX(Dívidas!$C$8:$C$17,MATCH(LARGE(Dívidas!$G$8:$G$17,4),Dívidas!$G$8:$G$17,0)))>0,INDEX(Dívidas!$B$8:$B$17,MATCH(LARGE(Dívidas!$G$8:$G$17,4),Dívidas!$G$8:$G$17,0)),"") -> Compra parcelada na loja | D9: =IF(N(INDEX(Dívidas!$C$8:$C$17,MATCH(LARGE(Dívidas!$G$8:$G$17,4),Dívidas!$G$8:$G$17,0)))>0,N(INDEX(Dívidas!$C$8:$C$17,MATCH(LARGE(Dívidas!$G$8:$G$17,4),Dívidas!$G$8:$G$17,0))),0) -> 900 | E9: =IF(N(INDEX(Dívidas!$C$8:$C$17,MATCH(LARGE(Dívidas!$G$8:$G$17,4),Dívidas!$G$8:$G$17,0)))>0,N(INDEX(Dívidas!$D$8:$D$17,MATCH(LARGE(Dívidas!$G$8:$G$17,4),Dívidas!$G$8:$G$17,0))),0) -> 0 | F9: =IF(N(INDEX(Dívidas!$C$8:$C$17,MATCH(LARGE(Dívidas!$G$8:$G$17,4),Dívidas!$G$8:$G$17,0)))>0,N(INDEX(Dívidas!$E$8:$E$17,MATCH(LARGE(Dívidas!$G$8:$G$17,4),Dívidas!$G$8:$G$17,0))),0) -> 150 | H9: 4 | I9: =IF(N(INDEX(Dívidas!$C$8:$C$17,MATCH(SMALL(Dívidas!$H$8:$H$17,4),Dívidas!$H$8:$H$17,0)))>0,INDEX(Dívidas!$B$8:$B$17,MATCH(SMALL(Dívidas!$H$8:$H$17,4),Dívidas!$H$8:$H$17,0)),"") -> Empréstimo pessoal | J9: =IF(N(INDEX(Dívidas!$C$8:$C$17,MATCH(SMALL(Dívidas!$H$8:$H$17,4),Dívidas!$H$8:$H$17,0)))>0,N(INDEX(Dívidas!$C$8:$C$17,MATCH(SMALL(Dívidas!$H$8:$H$17,4),Dívidas!$H$8:$H$17,0))),0) -> 8000 | K9: =IF(N(INDEX(Dívidas!$C$8:$C$17,MATCH(SMALL(Dívidas!$H$8:$H$17,4),Dívidas!$H$8:$H$17,0)))>0,N(INDEX(Dívidas!$D$8:$D$17,MATCH(SMALL(Dívidas!$H$8:$H$17,4),Dívidas!$H$8:$H$17,0))),0) -> 0.035 | L9: =IF(N(INDEX(Dívidas!$C$8:$C$17,MATCH(SMALL(Dívidas!$H$8:$H$17,4),Dívidas!$H$8:$H$17,0)))>0,N(INDEX(Dívidas!$E$8:$E$17,MATCH(SMALL(Dívidas!$H$8:$H$17,4),Dívidas!$H$8:$H$17,0))),0) -> 450
B10: 5 | C10: =IF(N(INDEX(Dívidas!$C$8:$C$17,MATCH(LARGE(Dívidas!$G$8:$G$17,5),Dívidas!$G$8:$G$17,0)))>0,INDEX(Dívidas!$B$8:$B$17,MATCH(LARGE(Dívidas!$G$8:$G$17,5),Dívidas!$G$8:$G$17,0)),"") | D10: =IF(N(INDEX(Dívidas!$C$8:$C$17,MATCH(LARGE(Dívidas!$G$8:$G$17,5),Dívidas!$G$8:$G$17,0)))>0,N(INDEX(Dívidas!$C$8:$C$17,MATCH(LARGE(Dívidas!$G$8:$G$17,5),Dívidas!$G$8:$G$17,0))),0) -> 0 | E10: =IF(N(INDEX(Dívidas!$C$8:$C$17,MATCH(LARGE(Dívidas!$G$8:$G$17,5),Dívidas!$G$8:$G$17,0)))>0,N(INDEX(Dívidas!$D$8:$D$17,MATCH(LARGE(Dívidas!$G$8:$G$17,5),Dívidas!$G$8:$G$17,0))),0) -> 0 | F10: =IF(N(INDEX(Dívidas!$C$8:$C$17,MATCH(LARGE(Dívidas!$G$8:$G$17,5),Dívidas!$G$8:$G$17,0)))>0,N(INDEX(Dívidas!$E$8:$E$17,MATCH(LARGE(Dívidas!$G$8:$G$17,5),Dívidas!$G$8:$G$17,0))),0) -> 0 | H10: 5 | I10: =IF(N(INDEX(Dívidas!$C$8:$C$17,MATCH(SMALL(Dívidas!$H$8:$H$17,5),Dívidas!$H$8:$H$17,0)))>0,INDEX(Dívidas!$B$8:$B$17,MATCH(SMALL(Dívidas!$H$8:$H$17,5),Dívidas!$H$8:$H$17,0)),"") | J10: =IF(N(INDEX(Dívidas!$C$8:$C$17,MATCH(SMALL(Dívidas!$H$8:$H$17,5),Dívidas!$H$8:$H$17,0)))>0,N(INDEX(Dívidas!$C$8:$C$17,MATCH(SMALL(Dívidas!$H$8:$H$17,5),Dívidas!$H$8:$H$17,0))),0) -> 0 | K10: =IF(N(INDEX(Dívidas!$C$8:$C$17,MATCH(SMALL(Dívidas!$H$8:$H$17,5),Dívidas!$H$8:$H$17,0)))>0,N(INDEX(Dívidas!$D$8:$D$17,MATCH(SMALL(Dívidas!$H$8:$H$17,5),Dívidas!$H$8:$H$17,0))),0) -> 0 | L10: =IF(N(INDEX(Dívidas!$C$8:$C$17,MATCH(SMALL(Dívidas!$H$8:$H$17,5),Dívidas!$H$8:$H$17,0)))>0,N(INDEX(Dívidas!$E$8:$E$17,MATCH(SMALL(Dívidas!$H$8:$H$17,5),Dívidas!$H$8:$H$17,0))),0) -> 0
B11: 6 | C11: =IF(N(INDEX(Dívidas!$C$8:$C$17,MATCH(LARGE(Dívidas!$G$8:$G$17,6),Dívidas!$G$8:$G$17,0)))>0,INDEX(Dívidas!$B$8:$B$17,MATCH(LARGE(Dívidas!$G$8:$G$17,6),Dívidas!$G$8:$G$17,0)),"") | D11: =IF(N(INDEX(Dívidas!$C$8:$C$17,MATCH(LARGE(Dívidas!$G$8:$G$17,6),Dívidas!$G$8:$G$17,0)))>0,N(INDEX(Dívidas!$C$8:$C$17,MATCH(LARGE(Dívidas!$G$8:$G$17,6),Dívidas!$G$8:$G$17,0))),0) -> 0 | E11: =IF(N(INDEX(Dívidas!$C$8:$C$17,MATCH(LARGE(Dívidas!$G$8:$G$17,6),Dívidas!$G$8:$G$17,0)))>0,N(INDEX(Dívidas!$D$8:$D$17,MATCH(LARGE(Dívidas!$G$8:$G$17,6),Dívidas!$G$8:$G$17,0))),0) -> 0 | F11: =IF(N(INDEX(Dívidas!$C$8:$C$17,MATCH(LARGE(Dívidas!$G$8:$G$17,6),Dívidas!$G$8:$G$17,0)))>0,N(INDEX(Dívidas!$E$8:$E$17,MATCH(LARGE(Dívidas!$G$8:$G$17,6),Dívidas!$G$8:$G$17,0))),0) -> 0 | H11: 6 | I11: =IF(N(INDEX(Dívidas!$C$8:$C$17,MATCH(SMALL(Dívidas!$H$8:$H$17,6),Dívidas!$H$8:$H$17,0)))>0,INDEX(Dívidas!$B$8:$B$17,MATCH(SMALL(Dívidas!$H$8:$H$17,6),Dívidas!$H$8:$H$17,0)),"") | J11: =IF(N(INDEX(Dívidas!$C$8:$C$17,MATCH(SMALL(Dívidas!$H$8:$H$17,6),Dívidas!$H$8:$H$17,0)))>0,N(INDEX(Dívidas!$C$8:$C$17,MATCH(SMALL(Dívidas!$H$8:$H$17,6),Dívidas!$H$8:$H$17,0))),0) -> 0 | K11: =IF(N(INDEX(Dívidas!$C$8:$C$17,MATCH(SMALL(Dívidas!$H$8:$H$17,6),Dívidas!$H$8:$H$17,0)))>0,N(INDEX(Dívidas!$D$8:$D$17,MATCH(SMALL(Dívidas!$H$8:$H$17,6),Dívidas!$H$8:$H$17,0))),0) -> 0 | L11: =IF(N(INDEX(Dívidas!$C$8:$C$17,MATCH(SMALL(Dívidas!$H$8:$H$17,6),Dívidas!$H$8:$H$17,0)))>0,N(INDEX(Dívidas!$E$8:$E$17,MATCH(SMALL(Dívidas!$H$8:$H$17,6),Dívidas!$H$8:$H$17,0))),0) -> 0
B12: 7 | C12: =IF(N(INDEX(Dívidas!$C$8:$C$17,MATCH(LARGE(Dívidas!$G$8:$G$17,7),Dívidas!$G$8:$G$17,0)))>0,INDEX(Dívidas!$B$8:$B$17,MATCH(LARGE(Dívidas!$G$8:$G$17,7),Dívidas!$G$8:$G$17,0)),"") | D12: =IF(N(INDEX(Dívidas!$C$8:$C$17,MATCH(LARGE(Dívidas!$G$8:$G$17,7),Dívidas!$G$8:$G$17,0)))>0,N(INDEX(Dívidas!$C$8:$C$17,MATCH(LARGE(Dívidas!$G$8:$G$17,7),Dívidas!$G$8:$G$17,0))),0) -> 0 | E12: =IF(N(INDEX(Dívidas!$C$8:$C$17,MATCH(LARGE(Dívidas!$G$8:$G$17,7),Dívidas!$G$8:$G$17,0)))>0,N(INDEX(Dívidas!$D$8:$D$17,MATCH(LARGE(Dívidas!$G$8:$G$17,7),Dívidas!$G$8:$G$17,0))),0) -> 0 | F12: =IF(N(INDEX(Dívidas!$C$8:$C$17,MATCH(LARGE(Dívidas!$G$8:$G$17,7),Dívidas!$G$8:$G$17,0)))>0,N(INDEX(Dívidas!$E$8:$E$17,MATCH(LARGE(Dívidas!$G$8:$G$17,7),Dívidas!$G$8:$G$17,0))),0) -> 0 | H12: 7 | I12: =IF(N(INDEX(Dívidas!$C$8:$C$17,MATCH(SMALL(Dívidas!$H$8:$H$17,7),Dívidas!$H$8:$H$17,0)))>0,INDEX(Dívidas!$B$8:$B$17,MATCH(SMALL(Dívidas!$H$8:$H$17,7),Dívidas!$H$8:$H$17,0)),"") | J12: =IF(N(INDEX(Dívidas!$C$8:$C$17,MATCH(SMALL(Dívidas!$H$8:$H$17,7),Dívidas!$H$8:$H$17,0)))>0,N(INDEX(Dívidas!$C$8:$C$17,MATCH(SMALL(Dívidas!$H$8:$H$17,7),Dívidas!$H$8:$H$17,0))),0) -> 0 | K12: =IF(N(INDEX(Dívidas!$C$8:$C$17,MATCH(SMALL(Dívidas!$H$8:$H$17,7),Dívidas!$H$8:$H$17,0)))>0,N(INDEX(Dívidas!$D$8:$D$17,MATCH(SMALL(Dívidas!$H$8:$H$17,7),Dívidas!$H$8:$H$17,0))),0) -> 0 | L12: =IF(N(INDEX(Dívidas!$C$8:$C$17,MATCH(SMALL(Dívidas!$H$8:$H$17,7),Dívidas!$H$8:$H$17,0)))>0,N(INDEX(Dívidas!$E$8:$E$17,MATCH(SMALL(Dívidas!$H$8:$H$17,7),Dívidas!$H$8:$H$17,0))),0) -> 0
B13: 8 | C13: =IF(N(INDEX(Dívidas!$C$8:$C$17,MATCH(LARGE(Dívidas!$G$8:$G$17,8),Dívidas!$G$8:$G$17,0)))>0,INDEX(Dívidas!$B$8:$B$17,MATCH(LARGE(Dívidas!$G$8:$G$17,8),Dívidas!$G$8:$G$17,0)),"") | D13: =IF(N(INDEX(Dívidas!$C$8:$C$17,MATCH(LARGE(Dívidas!$G$8:$G$17,8),Dívidas!$G$8:$G$17,0)))>0,N(INDEX(Dívidas!$C$8:$C$17,MATCH(LARGE(Dívidas!$G$8:$G$17,8),Dívidas!$G$8:$G$17,0))),0) -> 0 | E13: =IF(N(INDEX(Dívidas!$C$8:$C$17,MATCH(LARGE(Dívidas!$G$8:$G$17,8),Dívidas!$G$8:$G$17,0)))>0,N(INDEX(Dívidas!$D$8:$D$17,MATCH(LARGE(Dívidas!$G$8:$G$17,8),Dívidas!$G$8:$G$17,0))),0) -> 0 | F13: =IF(N(INDEX(Dívidas!$C$8:$C$17,MATCH(LARGE(Dívidas!$G$8:$G$17,8),Dívidas!$G$8:$G$17,0)))>0,N(INDEX(Dívidas!$E$8:$E$17,MATCH(LARGE(Dívidas!$G$8:$G$17,8),Dívidas!$G$8:$G$17,0))),0) -> 0 | H13: 8 | I13: =IF(N(INDEX(Dívidas!$C$8:$C$17,MATCH(SMALL(Dívidas!$H$8:$H$17,8),Dívidas!$H$8:$H$17,0)))>0,INDEX(Dívidas!$B$8:$B$17,MATCH(SMALL(Dívidas!$H$8:$H$17,8),Dívidas!$H$8:$H$17,0)),"") | J13: =IF(N(INDEX(Dívidas!$C$8:$C$17,MATCH(SMALL(Dívidas!$H$8:$H$17,8),Dívidas!$H$8:$H$17,0)))>0,N(INDEX(Dívidas!$C$8:$C$17,MATCH(SMALL(Dívidas!$H$8:$H$17,8),Dívidas!$H$8:$H$17,0))),0) -> 0 | K13: =IF(N(INDEX(Dívidas!$C$8:$C$17,MATCH(SMALL(Dívidas!$H$8:$H$17,8),Dívidas!$H$8:$H$17,0)))>0,N(INDEX(Dívidas!$D$8:$D$17,MATCH(SMALL(Dívidas!$H$8:$H$17,8),Dívidas!$H$8:$H$17,0))),0) -> 0 | L13: =IF(N(INDEX(Dívidas!$C$8:$C$17,MATCH(SMALL(Dívidas!$H$8:$H$17,8),Dívidas!$H$8:$H$17,0)))>0,N(INDEX(Dívidas!$E$8:$E$17,MATCH(SMALL(Dívidas!$H$8:$H$17,8),Dívidas!$H$8:$H$17,0))),0) -> 0
B14: 9 | C14: =IF(N(INDEX(Dívidas!$C$8:$C$17,MATCH(LARGE(Dívidas!$G$8:$G$17,9),Dívidas!$G$8:$G$17,0)))>0,INDEX(Dívidas!$B$8:$B$17,MATCH(LARGE(Dívidas!$G$8:$G$17,9),Dívidas!$G$8:$G$17,0)),"") | D14: =IF(N(INDEX(Dívidas!$C$8:$C$17,MATCH(LARGE(Dívidas!$G$8:$G$17,9),Dívidas!$G$8:$G$17,0)))>0,N(INDEX(Dívidas!$C$8:$C$17,MATCH(LARGE(Dívidas!$G$8:$G$17,9),Dívidas!$G$8:$G$17,0))),0) -> 0 | E14: =IF(N(INDEX(Dívidas!$C$8:$C$17,MATCH(LARGE(Dívidas!$G$8:$G$17,9),Dívidas!$G$8:$G$17,0)))>0,N(INDEX(Dívidas!$D$8:$D$17,MATCH(LARGE(Dívidas!$G$8:$G$17,9),Dívidas!$G$8:$G$17,0))),0) -> 0 | F14: =IF(N(INDEX(Dívidas!$C$8:$C$17,MATCH(LARGE(Dívidas!$G$8:$G$17,9),Dívidas!$G$8:$G$17,0)))>0,N(INDEX(Dívidas!$E$8:$E$17,MATCH(LARGE(Dívidas!$G$8:$G$17,9),Dívidas!$G$8:$G$17,0))),0) -> 0 | H14: 9 | I14: =IF(N(INDEX(Dívidas!$C$8:$C$17,MATCH(SMALL(Dívidas!$H$8:$H$17,9),Dívidas!$H$8:$H$17,0)))>0,INDEX(Dívidas!$B$8:$B$17,MATCH(SMALL(Dívidas!$H$8:$H$17,9),Dívidas!$H$8:$H$17,0)),"") | J14: =IF(N(INDEX(Dívidas!$C$8:$C$17,MATCH(SMALL(Dívidas!$H$8:$H$17,9),Dívidas!$H$8:$H$17,0)))>0,N(INDEX(Dívidas!$C$8:$C$17,MATCH(SMALL(Dívidas!$H$8:$H$17,9),Dívidas!$H$8:$H$17,0))),0) -> 0 | K14: =IF(N(INDEX(Dívidas!$C$8:$C$17,MATCH(SMALL(Dívidas!$H$8:$H$17,9),Dívidas!$H$8:$H$17,0)))>0,N(INDEX(Dívidas!$D$8:$D$17,MATCH(SMALL(Dívidas!$H$8:$H$17,9),Dívidas!$H$8:$H$17,0))),0) -> 0 | L14: =IF(N(INDEX(Dívidas!$C$8:$C$17,MATCH(SMALL(Dívidas!$H$8:$H$17,9),Dívidas!$H$8:$H$17,0)))>0,N(INDEX(Dívidas!$E$8:$E$17,MATCH(SMALL(Dívidas!$H$8:$H$17,9),Dívidas!$H$8:$H$17,0))),0) -> 0
B15: 10 | C15: =IF(N(INDEX(Dívidas!$C$8:$C$17,MATCH(LARGE(Dívidas!$G$8:$G$17,10),Dívidas!$G$8:$G$17,0)))>0,INDEX(Dívidas!$B$8:$B$17,MATCH(LARGE(Dívidas!$G$8:$G$17,10),Dívidas!$G$8:$G$17,0)),"") | D15: =IF(N(INDEX(Dívidas!$C$8:$C$17,MATCH(LARGE(Dívidas!$G$8:$G$17,10),Dívidas!$G$8:$G$17,0)))>0,N(INDEX(Dívidas!$C$8:$C$17,MATCH(LARGE(Dívidas!$G$8:$G$17,10),Dívidas!$G$8:$G$17,0))),0) -> 0 | E15: =IF(N(INDEX(Dívidas!$C$8:$C$17,MATCH(LARGE(Dívidas!$G$8:$G$17,10),Dívidas!$G$8:$G$17,0)))>0,N(INDEX(Dívidas!$D$8:$D$17,MATCH(LARGE(Dívidas!$G$8:$G$17,10),Dívidas!$G$8:$G$17,0))),0) -> 0 | F15: =IF(N(INDEX(Dívidas!$C$8:$C$17,MATCH(LARGE(Dívidas!$G$8:$G$17,10),Dívidas!$G$8:$G$17,0)))>0,N(INDEX(Dívidas!$E$8:$E$17,MATCH(LARGE(Dívidas!$G$8:$G$17,10),Dívidas!$G$8:$G$17,0))),0) -> 0 | H15: 10 | I15: =IF(N(INDEX(Dívidas!$C$8:$C$17,MATCH(SMALL(Dívidas!$H$8:$H$17,10),Dívidas!$H$8:$H$17,0)))>0,INDEX(Dívidas!$B$8:$B$17,MATCH(SMALL(Dívidas!$H$8:$H$17,10),Dívidas!$H$8:$H$17,0)),"") | J15: =IF(N(INDEX(Dívidas!$C$8:$C$17,MATCH(SMALL(Dívidas!$H$8:$H$17,10),Dívidas!$H$8:$H$17,0)))>0,N(INDEX(Dívidas!$C$8:$C$17,MATCH(SMALL(Dívidas!$H$8:$H$17,10),Dívidas!$H$8:$H$17,0))),0) -> 0 | K15: =IF(N(INDEX(Dívidas!$C$8:$C$17,MATCH(SMALL(Dívidas!$H$8:$H$17,10),Dívidas!$H$8:$H$17,0)))>0,N(INDEX(Dívidas!$D$8:$D$17,MATCH(SMALL(Dívidas!$H$8:$H$17,10),Dívidas!$H$8:$H$17,0))),0) -> 0 | L15: =IF(N(INDEX(Dívidas!$C$8:$C$17,MATCH(SMALL(Dívidas!$H$8:$H$17,10),Dívidas!$H$8:$H$17,0)))>0,N(INDEX(Dívidas!$E$8:$E$17,MATCH(SMALL(Dívidas!$H$8:$H$17,10),Dívidas!$H$8:$H$17,0))),0) -> 0

Sheet Sim Avalanche
A1: Simulação mês a mês · Avalanche
A2: Cálculo automático. Não precisa mexer aqui.
A4: Mês | B4: Sobra p/ extra | C4: 1ª · Devido | D4: 1ª · Mínima | E4: 1ª · Extra | F4: 1ª · Saldo | G4: 2ª · Devido | H4: 2ª · Mínima | I4: 2ª · Extra | J4: 2ª · Saldo | K4: 3ª · Devido | L4: 3ª · Mínima | M4: 3ª · Extra | N4: 3ª · Saldo | O4: 4ª · Devido | P4: 4ª · Mínima | Q4: 4ª · Extra | R4: 4ª · Saldo | S4: 5ª · Devido | T4: 5ª · Mínima | U4: 5ª · Extra | V4: 5ª · Saldo | W4: 6ª · Devido | X4: 6ª · Mínima | Y4: 6ª · Extra | Z4: 6ª · Saldo | AA4: 7ª · Devido | AB4: 7ª · Mínima | AC4: 7ª · Extra | AD4: 7ª · Saldo | AE4: 8ª · Devido | AF4: 8ª · Mínima | AG4: 8ª · Extra | AH4: 8ª · Saldo | AI4: 9ª · Devido | AJ4: 9ª · Mínima | AK4: 9ª · Extra | AL4: 9ª · Saldo | AM4: 10ª · Devido | AN4: 10ª · Mínima | AO4: 10ª · Extra | AP4: 10ª · Saldo | AQ4: Saldo total | AR4: Pago no mês
A5: 1 | B5: =MAX(0,Dívidas!$C$20-(D5+H5+L5+P5+T5+X5+AB5+AF5+AJ5+AN5)) -> 400 | C5: =IF(Ordem!$D$6>0.005,Ordem!$D$6*(1+Ordem!$E$6),0) -> 3360 | D5: =MIN(C5,Ordem!$F$6) -> 300 | E5: =MAX(0,MIN(C5-D5,$B5-(0))) -> 400 | F5: =MAX(0,C5-D5-E5) -> 2660 | G5: =IF(Ordem!$D$7>0.005,Ordem!$D$7*(1+Ordem!$E$7),0) -> 1296 | H5: =MIN(G5,Ordem!$F$7) -> 150 | I5: =MAX(0,MIN(G5-H5,$B5-(E5))) -> 0 | J5: =MAX(0,G5-H5-I5) -> 1146 | K5: =IF(Ordem!$D$8>0.005,Ordem!$D$8*(1+Ordem!$E$8),0) -> 8280 | L5: =MIN(K5,Ordem!$F$8) -> 450 | M5: =MAX(0,MIN(K5-L5,$B5-(E5+I5))) -> 0 | N5: =MAX(0,K5-L5-M5) -> 7830 | O5: =IF(Ordem!$D$9>0.005,Ordem!$D$9*(1+Ordem!$E$9),0) -> 900 | P5: =MIN(O5,Ordem!$F$9) -> 150 | Q5: =MAX(0,MIN(O5-P5,$B5-(E5+I5+M5))) -> 0 | R5: =MAX(0,O5-P5-Q5) -> 750 | S5: =IF(Ordem!$D$10>0.005,Ordem!$D$10*(1+Ordem!$E$10),0) -> 0 | T5: =MIN(S5,Ordem!$F$10) -> 0 | U5: =MAX(0,MIN(S5-T5,$B5-(E5+I5+M5+Q5))) -> 0 | V5: =MAX(0,S5-T5-U5) -> 0 | W5: =IF(Ordem!$D$11>0.005,Ordem!$D$11*(1+Ordem!$E$11),0) -> 0 | X5: =MIN(W5,Ordem!$F$11) -> 0 | Y5: =MAX(0,MIN(W5-X5,$B5-(E5+I5+M5+Q5+U5))) -> 0 | Z5: =MAX(0,W5-X5-Y5) -> 0 | AA5: =IF(Ordem!$D$12>0.005,Ordem!$D$12*(1+Ordem!$E$12),0) -> 0 | AB5: =MIN(AA5,Ordem!$F$12) -> 0 | AC5: =MAX(0,MIN(AA5-AB5,$B5-(E5+I5+M5+Q5+U5+Y5))) -> 0 | AD5: =MAX(0,AA5-AB5-AC5) -> 0 | AE5: =IF(Ordem!$D$13>0.005,Ordem!$D$13*(1+Ordem!$E$13),0) -> 0 | AF5: =MIN(AE5,Ordem!$F$13) -> 0 | AG5: =MAX(0,MIN(AE5-AF5,$B5-(E5+I5+M5+Q5+U5+Y5+AC5))) -> 0 | AH5: =MAX(0,AE5-AF5-AG5) -> 0 | AI5: =IF(Ordem!$D$14>0.005,Ordem!$D$14*(1+Ordem!$E$14),0) -> 0 | AJ5: =MIN(AI5,Ordem!$F$14) -> 0 | AK5: =MAX(0,MIN(AI5-AJ5,$B5-(E5+I5+M5+Q5+U5+Y5+AC5+AG5))) -> 0 | AL5: =MAX(0,AI5-AJ5-AK5) -> 0 | AM5: =IF(Ordem!$D$15>0.005,Ordem!$D$15*(1+Ordem!$E$15),0) -> 0 | AN5: =MIN(AM5,Ordem!$F$15) -> 0 | AO5: =MAX(0,MIN(AM5-AN5,$B5-(E5+I5+M5+Q5+U5+Y5+AC5+AG5+AK5))) -> 0 | AP5: =MAX(0,AM5-AN5-AO5) -> 0 | AQ5: =F5+J5+N5+R5+V5+Z5+AD5+AH5+AL5+AP5 -> 12386 | AR5: =D5+E5+H5+I5+L5+M5+P5+Q5+T5+U5+X5+Y5+AB5+AC5+AF5+AG5+AJ5+AK5+AN5+AO5 -> 1450
A6: 2 | B6: =MAX(0,Dívidas!$C$20-(D6+H6+L6+P6+T6+X6+AB6+AF6+AJ6+AN6)) -> 400 | C6: =IF(F5>0.005,F5*(1+Ordem!$E$6),0) -> 2979.2 | D6: =MIN(C6,Ordem!$F$6) -> 300 | E6: =MAX(0,MIN(C6-D6,$B6-(0))) -> 400 | F6: =MAX(0,C6-D6-E6) -> 2279.2 | G6: =IF(J5>0.005,J5*(1+Ordem!$E$7),0) -> 1237.68 | H6: =MIN(G6,Ordem!$F$7) -> 150 | I6: =MAX(0,MIN(G6-H6,$B6-(E6))) -> 0 | J6: =MAX(0,G6-H6-I6) -> 1087.68 | K6: =IF(N5>0.005,N5*(1+Ordem!$E$8),0) -> 8104.05 | L6: =MIN(K6,Ordem!$F$8) -> 450 | M6: =MAX(0,MIN(K6-L6,$B6-(E6+I6))) -> 0 | N6: =MAX(0,K6-L6-M6) -> 7654.05 | O6: =IF(R5>0.005,R5*(1+Ordem!$E$9),0) -> 750 | P6: =MIN(O6,Ordem!$F$9) -> 150 | Q6: =MAX(0,MIN(O6-P6,$B6-(E6+I6+M6))) -> 0 | R6: =MAX(0,O6-P6-Q6) -> 600 | S6: =IF(V5>0.005,V5*(1+Ordem!$E$10),0) -> 0 | T6: =MIN(S6,Ordem!$F$10) -> 0 | U6: =MAX(0,MIN(S6-T6,$B6-(E6+I6+M6+Q6))) -> 0 | V6: =MAX(0,S6-T6-U6) -> 0 | W6: =IF(Z5>0.005,Z5*(1+Ordem!$E$11),0) -> 0 | X6: =MIN(W6,Ordem!$F$11) -> 0 | Y6: =MAX(0,MIN(W6-X6,$B6-(E6+I6+M6+Q6+U6))) -> 0 | Z6: =MAX(0,W6-X6-Y6) -> 0 | AA6: =IF(AD5>0.005,AD5*(1+Ordem!$E$12),0) -> 0 | AB6: =MIN(AA6,Ordem!$F$12) -> 0 | AC6: =MAX(0,MIN(AA6-AB6,$B6-(E6+I6+M6+Q6+U6+Y6))) -> 0 | AD6: =MAX(0,AA6-AB6-AC6) -> 0 | AE6: =IF(AH5>0.005,AH5*(1+Ordem!$E$13),0) -> 0 | AF6: =MIN(AE6,Ordem!$F$13) -> 0 | AG6: =MAX(0,MIN(AE6-AF6,$B6-(E6+I6+M6+Q6+U6+Y6+AC6))) -> 0 | AH6: =MAX(0,AE6-AF6-AG6) -> 0 | AI6: =IF(AL5>0.005,AL5*(1+Ordem!$E$14),0) -> 0 | AJ6: =MIN(AI6,Ordem!$F$14) -> 0 | AK6: =MAX(0,MIN(AI6-AJ6,$B6-(E6+I6+M6+Q6+U6+Y6+AC6+AG6))) -> 0 | AL6: =MAX(0,AI6-AJ6-AK6) -> 0 | AM6: =IF(AP5>0.005,AP5*(1+Ordem!$E$15),0) -> 0 | AN6: =MIN(AM6,Ordem!$F$15) -> 0 | AO6: =MAX(0,MIN(AM6-AN6,$B6-(E6+I6+M6+Q6+U6+Y6+AC6+AG6+AK6))) -> 0 | AP6: =MAX(0,AM6-AN6-AO6) -> 0 | AQ6: =F6+J6+N6+R6+V6+Z6+AD6+AH6+AL6+AP6 -> 11620.93 | AR6: =D6+E6+H6+I6+L6+M6+P6+Q6+T6+U6+X6+Y6+AB6+AC6+AF6+AG6+AJ6+AK6+AN6+AO6 -> 1450
A7: 3 | B7: =MAX(0,Dívidas!$C$20-(D7+H7+L7+P7+T7+X7+AB7+AF7+AJ7+AN7)) -> 400 | C7: =IF(F6>0.005,F6*(1+Ordem!$E$6),0) -> 2552.704 | D7: =MIN(C7,Ordem!$F$6) -> 300 | E7: =MAX(0,MIN(C7-D7,$B7-(0))) -> 400 | F7: =MAX(0,C7-D7-E7) -> 1852.704 | G7: =IF(J6>0.005,J6*(1+Ordem!$E$7),0) -> 1174.6944 | H7: =MIN(G7,Ordem!$F$7) -> 150 | I7: =MAX(0,MIN(G7-H7,$B7-(E7))) -> 0 | J7: =MAX(0,G7-H7-I7) -> 1024.6944 | K7: =IF(N6>0.005,N6*(1+Ordem!$E$8),0) -> 7921.9417 | L7: =MIN(K7,Ordem!$F$8) -> 450 | M7: =MAX(0,MIN(K7-L7,$B7-(E7+I7))) -> 0 | N7: =MAX(0,K7-L7-M7) -> 7471.9417 | O7: =IF(R6>0.005,R6*(1+Ordem!$E$9),0) -> 600 | P7: =MIN(O7,Ordem!$F$9) -> 150 | Q7: =MAX(0,MIN(O7-P7,$B7-(E7+I7+M7))) -> 0 | R7: =MAX(0,O7-P7-Q7) -> 450 | S7: =IF(V6>0.005,V6*(1+Ordem!$E$10),0) -> 0 | T7: =MIN(S7,Ordem!$F$10) -> 0 | U7: =MAX(0,MIN(S7-T7,$B7-(E7+I7+M7+Q7))) -> 0 | V7: =MAX(0,S7-T7-U7) -> 0 | W7: =IF(Z6>0.005,Z6*(1+Ordem!$E$11),0) -> 0 | X7: =MIN(W7,Ordem!$F$11) -> 0 | Y7: =MAX(0,MIN(W7-X7,$B7-(E7+I7+M7+Q7+U7))) -> 0 | Z7: =MAX(0,W7-X7-Y7) -> 0 | AA7: =IF(AD6>0.005,AD6*(1+Ordem!$E$12),0) -> 0 | AB7: =MIN(AA7,Ordem!$F$12) -> 0 | AC7: =MAX(0,MIN(AA7-AB7,$B7-(E7+I7+M7+Q7+U7+Y7))) -> 0 | AD7: =MAX(0,AA7-AB7-AC7) -> 0 | AE7: =IF(AH6>0.005,AH6*(1+Ordem!$E$13),0) -> 0 | AF7: =MIN(AE7,Ordem!$F$13) -> 0 | AG7: =MAX(0,MIN(AE7-AF7,$B7-(E7+I7+M7+Q7+U7+Y7+AC7))) -> 0 | AH7: =MAX(0,AE7-AF7-AG7) -> 0 | AI7: =IF(AL6>0.005,AL6*(1+Ordem!$E$14),0) -> 0 | AJ7: =MIN(AI7,Ordem!$F$14) -> 0 | AK7: =MAX(0,MIN(AI7-AJ7,$B7-(E7+I7+M7+Q7+U7+Y7+AC7+AG7))) -> 0 | AL7: =MAX(0,AI7-AJ7-AK7) -> 0 | AM7: =IF(AP6>0.005,AP6*(1+Ordem!$E$15),0) -> 0 | AN7: =MIN(AM7,Ordem!$F$15) -> 0 | AO7: =MAX(0,MIN(AM7-AN7,$B7-(E7+I7+M7+Q7+U7+Y7+AC7+AG7+AK7))) -> 0 | AP7: =MAX(0,AM7-AN7-AO7) -> 0 | AQ7: =F7+J7+N7+R7+V7+Z7+AD7+AH7+AL7+AP7 -> 10799.34 | AR7: =D7+E7+H7+I7+L7+M7+P7+Q7+T7+U7+X7+Y7+AB7+AC7+AF7+AG7+AJ7+AK7+AN7+AO7 -> 1450
A8: 4 | B8: =MAX(0,Dívidas!$C$20-(D8+H8+L8+P8+T8+X8+AB8+AF8+AJ8+AN8)) -> 400 | C8: =IF(F7>0.005,F7*(1+Ordem!$E$6),0) -> 2075.0285 | D8: =MIN(C8,Ordem!$F$6) -> 300 | E8: =MAX(0,MIN(C8-D8,$B8-(0))) -> 400 | F8: =MAX(0,C8-D8-E8) -> 1375.0285 | G8: =IF(J7>0.005,J7*(1+Ordem!$E$7),0) -> 1106.67 | H8: =MIN(G8,Ordem!$F$7) -> 150 | I8: =MAX(0,MIN(G8-H8,$B8-(E8))) -> 0 | J8: =MAX(0,G8-H8-I8) -> 956.66995 | K8: =IF(N7>0.005,N7*(1+Ordem!$E$8),0) -> 7733.4597 | L8: =MIN(K8,Ordem!$F$8) -> 450 | M8: =MAX(0,MIN(K8-L8,$B8-(E8+I8))) -> 0 | N8: =MAX(0,K8-L8-M8) -> 7283.4597 | O8: =IF(R7>0.005,R7*(1+Ordem!$E$9),0) -> 450 | P8: =MIN(O8,Ordem!$F$9) -> 150 | Q8: =MAX(0,MIN(O8-P8,$B8-(E8+I8+M8))) -> 0 | R8: =MAX(0,O8-P8-Q8) -> 300 | S8: =IF(V7>0.005,V7*(1+Ordem!$E$10),0) -> 0 | T8: =MIN(S8,Ordem!$F$10) -> 0 | U8: =MAX(0,MIN(S8-T8,$B8-(E8+I8+M8+Q8))) -> 0 | V8: =MAX(0,S8-T8-U8) -> 0 | W8: =IF(Z7>0.005,Z7*(1+Ordem!$E$11),0) -> 0 | X8: =MIN(W8,Ordem!$F$11) -> 0 | Y8: =MAX(0,MIN(W8-X8,$B8-(E8+I8+M8+Q8+U8))) -> 0 | Z8: =MAX(0,W8-X8-Y8) -> 0 | AA8: =IF(AD7>0.005,AD7*(1+Ordem!$E$12),0) -> 0 | AB8: =MIN(AA8,Ordem!$F$12) -> 0 | AC8: =MAX(0,MIN(AA8-AB8,$B8-(E8+I8+M8+Q8+U8+Y8))) -> 0 | AD8: =MAX(0,AA8-AB8-AC8) -> 0 | AE8: =IF(AH7>0.005,AH7*(1+Ordem!$E$13),0) -> 0 | AF8: =MIN(AE8,Ordem!$F$13) -> 0 | AG8: =MAX(0,MIN(AE8-AF8,$B8-(E8+I8+M8+Q8+U8+Y8+AC8))) -> 0 | AH8: =MAX(0,AE8-AF8-AG8) -> 0 | AI8: =IF(AL7>0.005,AL7*(1+Ordem!$E$14),0) -> 0 | AJ8: =MIN(AI8,Ordem!$F$14) -> 0 | AK8: =MAX(0,MIN(AI8-AJ8,$B8-(E8+I8+M8+Q8+U8+Y8+AC8+AG8))) -> 0 | AL8: =MAX(0,AI8-AJ8-AK8) -> 0 | AM8: =IF(AP7>0.005,AP7*(1+Ordem!$E$15),0) -> 0 | AN8: =MIN(AM8,Ordem!$F$15) -> 0 | AO8: =MAX(0,MIN(AM8-AN8,$B8-(E8+I8+M8+Q8+U8+Y8+AC8+AG8+AK8))) -> 0 | AP8: =MAX(0,AM8-AN8-AO8) -> 0 | AQ8: =F8+J8+N8+R8+V8+Z8+AD8+AH8+AL8+AP8 -> 9915.1581 | AR8: =D8+E8+H8+I8+L8+M8+P8+Q8+T8+U8+X8+Y8+AB8+AC8+AF8+AG8+AJ8+AK8+AN8+AO8 -> 1450
A9: 5 | B9: =MAX(0,Dívidas!$C$20-(D9+H9+L9+P9+T9+X9+AB9+AF9+AJ9+AN9)) -> 400 | C9: =IF(F8>0.005,F8*(1+Ordem!$E$6),0) -> 1540.0319 | D9: =MIN(C9,Ordem!$F$6) -> 300 | E9: =MAX(0,MIN(C9-D9,$B9-(0))) -> 400 | F9: =MAX(0,C9-D9-E9) -> 840.0319 | G9: =IF(J8>0.005,J8*(1+Ordem!$E$7),0) -> 1033.2035 | H9: =MIN(G9,Ordem!$F$7) -> 150 | I9: =MAX(0,MIN(G9-H9,$B9-(E9))) -> 0 | J9: =MAX(0,G9-H9-I9) -> 883.20355 | K9: =IF(N8>0.005,N8*(1+Ordem!$E$8),0) -> 7538.3808 | L9: =MIN(K9,Ordem!$F$8) -> 450 | M9: =MAX(0,MIN(K9-L9,$B9-(E9+I9))) -> 0 | N9: =MAX(0,K9-L9-M9) -> 7088.3808 | O9: =IF(R8>0.005,R8*(1+Ordem!$E$9),0) -> 300 | P9: =MIN(O9,Ordem!$F$9) -> 150 | Q9: =MAX(0,MIN(O9-P9,$B9-(E9+I9+M9))) -> 0 | R9: =MAX(0,O9-P9-Q9) -> 150 | S9: =IF(V8>0.005,V8*(1+Ordem!$E$10),0) -> 0 | T9: =MIN(S9,Ordem!$F$10) -> 0 | U9: =MAX(0,MIN(S9-T9,$B9-(E9+I9+M9+Q9))) -> 0 | V9: =MAX(0,S9-T9-U9) -> 0 | W9: =IF(Z8>0.005,Z8*(1+Ordem!$E$11),0) -> 0 | X9: =MIN(W9,Ordem!$F$11) -> 0 | Y9: =MAX(0,MIN(W9-X9,$B9-(E9+I9+M9+Q9+U9))) -> 0 | Z9: =MAX(0,W9-X9-Y9) -> 0 | AA9: =IF(AD8>0.005,AD8*(1+Ordem!$E$12),0) -> 0 | AB9: =MIN(AA9,Ordem!$F$12) -> 0 | AC9: =MAX(0,MIN(AA9-AB9,$B9-(E9+I9+M9+Q9+U9+Y9))) -> 0 | AD9: =MAX(0,AA9-AB9-AC9) -> 0 | AE9: =IF(AH8>0.005,AH8*(1+Ordem!$E$13),0) -> 0 | AF9: =MIN(AE9,Ordem!$F$13) -> 0 | AG9: =MAX(0,MIN(AE9-AF9,$B9-(E9+I9+M9+Q9+U9+Y9+AC9))) -> 0 | AH9: =MAX(0,AE9-AF9-AG9) -> 0 | AI9: =IF(AL8>0.005,AL8*(1+Ordem!$E$14),0) -> 0 | AJ9: =MIN(AI9,Ordem!$F$14) -> 0 | AK9: =MAX(0,MIN(AI9-AJ9,$B9-(E9+I9+M9+Q9+U9+Y9+AC9+AG9))) -> 0 | AL9: =MAX(0,AI9-AJ9-AK9) -> 0 | AM9: =IF(AP8>0.005,AP8*(1+Ordem!$E$15),0) -> 0 | AN9: =MIN(AM9,Ordem!$F$15) -> 0 | AO9: =MAX(0,MIN(AM9-AN9,$B9-(E9+I9+M9+Q9+U9+Y9+AC9+AG9+AK9))) -> 0 | AP9: =MAX(0,AM9-AN9-AO9) -> 0 | AQ9: =F9+J9+N9+R9+V9+Z9+AD9+AH9+AL9+AP9 -> 8961.6162 | AR9: =D9+E9+H9+I9+L9+M9+P9+Q9+T9+U9+X9+Y9+AB9+AC9+AF9+AG9+AJ9+AK9+AN9+AO9 -> 1450
A10: 6 | B10: =MAX(0,Dívidas!$C$20-(D10+H10+L10+P10+T10+X10+AB10+AF10+AJ10+AN10)) -> 400 | C10: =IF(F9>0.005,F9*(1+Ordem!$E$6),0) -> 940.83573 | D10: =MIN(C10,Ordem!$F$6) -> 300 | E10: =MAX(0,MIN(C10-D10,$B10-(0))) -> 400 | F10: =MAX(0,C10-D10-E10) -> 240.83573 | G10: =IF(J9>0.005,J9*(1+Ordem!$E$7),0) -> 953.85983 | H10: =MIN(G10,Ordem!$F$7) -> 150 | I10: =MAX(0,MIN(G10-H10,$B10-(E10))) -> 0 | J10: =MAX(0,G10-H10-I10) -> 803.85983 | K10: =IF(N9>0.005,N9*(1+Ordem!$E$8),0) -> 7336.4741 | L10: =MIN(K10,Ordem!$F$8) -> 450 | M10: =MAX(0,MIN(K10-L10,$B10-(E10+I10))) -> 0 | N10: =MAX(0,K10-L10-M10) -> 6886.4741 | O10: =IF(R9>0.005,R9*(1+Ordem!$E$9),0) -> 150 | P10: =MIN(O10,Ordem!$F$9) -> 150 | Q10: =MAX(0,MIN(O10-P10,$B10-(E10+I10+M10))) -> 0 | R10: =MAX(0,O10-P10-Q10) -> 0 | S10: =IF(V9>0.005,V9*(1+Ordem!$E$10),0) -> 0 | T10: =MIN(S10,Ordem!$F$10) -> 0 | U10: =MAX(0,MIN(S10-T10,$B10-(E10+I10+M10+Q10))) -> 0 | V10: =MAX(0,S10-T10-U10) -> 0 | W10: =IF(Z9>0.005,Z9*(1+Ordem!$E$11),0) -> 0 | X10: =MIN(W10,Ordem!$F$11) -> 0 | Y10: =MAX(0,MIN(W10-X10,$B10-(E10+I10+M10+Q10+U10))) -> 0 | Z10: =MAX(0,W10-X10-Y10) -> 0 | AA10: =IF(AD9>0.005,AD9*(1+Ordem!$E$12),0) -> 0 | AB10: =MIN(AA10,Ordem!$F$12) -> 0 | AC10: =MAX(0,MIN(AA10-AB10,$B10-(E10+I10+M10+Q10+U10+Y10))) -> 0 | AD10: =MAX(0,AA10-AB10-AC10) -> 0 | AE10: =IF(AH9>0.005,AH9*(1+Ordem!$E$13),0) -> 0 | AF10: =MIN(AE10,Ordem!$F$13) -> 0 | AG10: =MAX(0,MIN(AE10-AF10,$B10-(E10+I10+M10+Q10+U10+Y10+AC10))) -> 0 | AH10: =MAX(0,AE10-AF10-AG10) -> 0 | AI10: =IF(AL9>0.005,AL9*(1+Ordem!$E$14),0) -> 0 | AJ10: =MIN(AI10,Ordem!$F$14) -> 0 | AK10: =MAX(0,MIN(AI10-AJ10,$B10-(E10+I10+M10+Q10+U10+Y10+AC10+AG10))) -> 0 | AL10: =MAX(0,AI10-AJ10-AK10) -> 0 | AM10: =IF(AP9>0.005,AP9*(1+Ordem!$E$15),0) -> 0 | AN10: =MIN(AM10,Ordem!$F$15) -> 0 | AO10: =MAX(0,MIN(AM10-AN10,$B10-(E10+I10+M10+Q10+U10+Y10+AC10+AG10+AK10))) -> 0 | AP10: =MAX(0,AM10-AN10-AO10) -> 0 | AQ10: =F10+J10+N10+R10+V10+Z10+AD10+AH10+AL10+AP10 -> 7931.1697 | AR10: =D10+E10+H10+I10+L10+M10+P10+Q10+T10+U10+X10+Y10+AB10+AC10+AF10+AG10+AJ10+AK10+AN10+AO10 -> 1450
A11: 7 | B11: =MAX(0,Dívidas!$C$20-(D11+H11+L11+P11+T11+X11+AB11+AF11+AJ11+AN11)) -> 580.26399 | C11: =IF(F10>0.005,F10*(1+Ordem!$E$6),0) -> 269.73601 | D11: =MIN(C11,Ordem!$F$6) -> 269.73601 | E11: =MAX(0,MIN(C11-D11,$B11-(0))) -> 0 | F11: =MAX(0,C11-D11-E11) -> 0 | G11: =IF(J10>0.005,J10*(1+Ordem!$E$7),0) -> 868.16862 | H11: =MIN(G11,Ordem!$F$7) -> 150 | I11: =MAX(0,MIN(G11-H11,$B11-(E11))) -> 580.26399 | J11: =MAX(0,G11-H11-I11) -> 137.90463 | K11: =IF(N10>0.005,N10*(1+Ordem!$E$8),0) -> 7127.5007 | L11: =MIN(K11,Ordem!$F$8) -> 450 | M11: =MAX(0,MIN(K11-L11,$B11-(E11+I11))) -> 0 | N11: =MAX(0,K11-L11-M11) -> 6677.5007 | O11: =IF(R10>0.005,R10*(1+Ordem!$E$9),0) -> 0 | P11: =MIN(O11,Ordem!$F$9) -> 0 | Q11: =MAX(0,MIN(O11-P11,$B11-(E11+I11+M11))) -> 0 | R11: =MAX(0,O11-P11-Q11) -> 0 | S11: =IF(V10>0.005,V10*(1+Ordem!$E$10),0) -> 0 | T11: =MIN(S11,Ordem!$F$10) -> 0 | U11: =MAX(0,MIN(S11-T11,$B11-(E11+I11+M11+Q11))) -> 0 | V11: =MAX(0,S11-T11-U11) -> 0 | W11: =IF(Z10>0.005,Z10*(1+Ordem!$E$11),0) -> 0 | X11: =MIN(W11,Ordem!$F$11) -> 0 | Y11: =MAX(0,MIN(W11-X11,$B11-(E11+I11+M11+Q11+U11))) -> 0 | Z11: =MAX(0,W11-X11-Y11) -> 0 | AA11: =IF(AD10>0.005,AD10*(1+Ordem!$E$12),0) -> 0 | AB11: =MIN(AA11,Ordem!$F$12) -> 0 | AC11: =MAX(0,MIN(AA11-AB11,$B11-(E11+I11+M11+Q11+U11+Y11))) -> 0 | AD11: =MAX(0,AA11-AB11-AC11) -> 0 | AE11: =IF(AH10>0.005,AH10*(1+Ordem!$E$13),0) -> 0 | AF11: =MIN(AE11,Ordem!$F$13) -> 0 | AG11: =MAX(0,MIN(AE11-AF11,$B11-(E11+I11+M11+Q11+U11+Y11+AC11))) -> 0 | AH11: =MAX(0,AE11-AF11-AG11) -> 0 | AI11: =IF(AL10>0.005,AL10*(1+Ordem!$E$14),0) -> 0 | AJ11: =MIN(AI11,Ordem!$F$14) -> 0 | AK11: =MAX(0,MIN(AI11-AJ11,$B11-(E11+I11+M11+Q11+U11+Y11+AC11+AG11))) -> 0 | AL11: =MAX(0,AI11-AJ11-AK11) -> 0 | AM11: =IF(AP10>0.005,AP10*(1+Ordem!$E$15),0) -> 0 | AN11: =MIN(AM11,Ordem!$F$15) -> 0 | AO11: =MAX(0,MIN(AM11-AN11,$B11-(E11+I11+M11+Q11+U11+Y11+AC11+AG11+AK11))) -> 0 | AP11: =MAX(0,AM11-AN11-AO11) -> 0 | AQ11: =F11+J11+N11+R11+V11+Z11+AD11+AH11+AL11+AP11 -> 6815.4054 | AR11: =D11+E11+H11+I11+L11+M11+P11+Q11+T11+U11+X11+Y11+AB11+AC11+AF11+AG11+AJ11+AK11+AN11+AO11 -> 1450
A12: 8 | B12: =MAX(0,Dívidas!$C$20-(D12+H12+L12+P12+T12+X12+AB12+AF12+AJ12+AN12)) -> 851.063 | C12: =IF(F11>0.005,F11*(1+Ordem!$E$6),0) -> 0 | D12: =MIN(C12,Ordem!$F$6) -> 0 | E12: =MAX(0,MIN(C12-D12,$B12-(0))) -> 0 | F12: =MAX(0,C12-D12-E12) -> 0 | G12: =IF(J11>0.005,J11*(1+Ordem!$E$7),0) -> 148.937 | H12: =MIN(G12,Ordem!$F$7) -> 148.937 | I12: =MAX(0,MIN(G12-H12,$B12-(E12))) -> 0 | J12: =MAX(0,G12-H12-I12) -> 0 | K12: =IF(N11>0.005,N11*(1+Ordem!$E$8),0) -> 6911.2132 | L12: =MIN(K12,Ordem!$F$8) -> 450 | M12: =MAX(0,MIN(K12-L12,$B12-(E12+I12))) -> 851.063 | N12: =MAX(0,K12-L12-M12) -> 5610.1503 | O12: =IF(R11>0.005,R11*(1+Ordem!$E$9),0) -> 0 | P12: =MIN(O12,Ordem!$F$9) -> 0 | Q12: =MAX(0,MIN(O12-P12,$B12-(E12+I12+M12))) -> 0 | R12: =MAX(0,O12-P12-Q12) -> 0 | S12: =IF(V11>0.005,V11*(1+Ordem!$E$10),0) -> 0 | T12: =MIN(S12,Ordem!$F$10) -> 0 | U12: =MAX(0,MIN(S12-T12,$B12-(E12+I12+M12+Q12))) -> 0 | V12: =MAX(0,S12-T12-U12) -> 0 | W12: =IF(Z11>0.005,Z11*(1+Ordem!$E$11),0) -> 0 | X12: =MIN(W12,Ordem!$F$11) -> 0 | Y12: =MAX(0,MIN(W12-X12,$B12-(E12+I12+M12+Q12+U12))) -> 0 | Z12: =MAX(0,W12-X12-Y12) -> 0 | AA12: =IF(AD11>0.005,AD11*(1+Ordem!$E$12),0) -> 0 | AB12: =MIN(AA12,Ordem!$F$12) -> 0 | AC12: =MAX(0,MIN(AA12-AB12,$B12-(E12+I12+M12+Q12+U12+Y12))) -> 0 | AD12: =MAX(0,AA12-AB12-AC12) -> 0 | AE12: =IF(AH11>0.005,AH11*(1+Ordem!$E$13),0) -> 0 | AF12: =MIN(AE12,Ordem!$F$13) -> 0 | AG12: =MAX(0,MIN(AE12-AF12,$B12-(E12+I12+M12+Q12+U12+Y12+AC12))) -> 0 | AH12: =MAX(0,AE12-AF12-AG12) -> 0 | AI12: =IF(AL11>0.005,AL11*(1+Ordem!$E$14),0) -> 0 | AJ12: =MIN(AI12,Ordem!$F$14) -> 0 | AK12: =MAX(0,MIN(AI12-AJ12,$B12-(E12+I12+M12+Q12+U12+Y12+AC12+AG12))) -> 0 | AL12: =MAX(0,AI12-AJ12-AK12) -> 0 | AM12: =IF(AP11>0.005,AP11*(1+Ordem!$E$15),0) -> 0 | AN12: =MIN(AM12,Ordem!$F$15) -> 0 | AO12: =MAX(0,MIN(AM12-AN12,$B12-(E12+I12+M12+Q12+U12+Y12+AC12+AG12+AK12))) -> 0 | AP12: =MAX(0,AM12-AN12-AO12) -> 0 | AQ12: =F12+J12+N12+R12+V12+Z12+AD12+AH12+AL12+AP12 -> 5610.1503 | AR12: =D12+E12+H12+I12+L12+M12+P12+Q12+T12+U12+X12+Y12+AB12+AC12+AF12+AG12+AJ12+AK12+AN12+AO12 -> 1450
A13: 9 | B13: =MAX(0,Dívidas!$C$20-(D13+H13+L13+P13+T13+X13+AB13+AF13+AJ13+AN13)) -> 1000 | C13: =IF(F12>0.005,F12*(1+Ordem!$E$6),0) -> 0 | D13: =MIN(C13,Ordem!$F$6) -> 0 | E13: =MAX(0,MIN(C13-D13,$B13-(0))) -> 0 | F13: =MAX(0,C13-D13-E13) -> 0 | G13: =IF(J12>0.005,J12*(1+Ordem!$E$7),0) -> 0 | H13: =MIN(G13,Ordem!$F$7) -> 0 | I13: =MAX(0,MIN(G13-H13,$B13-(E13))) -> 0 | J13: =MAX(0,G13-H13-I13) -> 0 | K13: =IF(N12>0.005,N12*(1+Ordem!$E$8),0) -> 5806.5055 | L13: =MIN(K13,Ordem!$F$8) -> 450 | M13: =MAX(0,MIN(K13-L13,$B13-(E13+I13))) -> 1000 | N13: =MAX(0,K13-L13-M13) -> 4356.5055 | O13: =IF(R12>0.005,R12*(1+Ordem!$E$9),0) -> 0 | P13: =MIN(O13,Ordem!$F$9) -> 0 | Q13: =MAX(0,MIN(O13-P13,$B13-(E13+I13+M13))) -> 0 | R13: =MAX(0,O13-P13-Q13) -> 0 | S13: =IF(V12>0.005,V12*(1+Ordem!$E$10),0) -> 0 | T13: =MIN(S13,Ordem!$F$10) -> 0 | U13: =MAX(0,MIN(S13-T13,$B13-(E13+I13+M13+Q13))) -> 0 | V13: =MAX(0,S13-T13-U13) -> 0 | W13: =IF(Z12>0.005,Z12*(1+Ordem!$E$11),0) -> 0 | X13: =MIN(W13,Ordem!$F$11) -> 0 | Y13: =MAX(0,MIN(W13-X13,$B13-(E13+I13+M13+Q13+U13))) -> 0 | Z13: =MAX(0,W13-X13-Y13) -> 0 | AA13: =IF(AD12>0.005,AD12*(1+Ordem!$E$12),0) -> 0 | AB13: =MIN(AA13,Ordem!$F$12) -> 0 | AC13: =MAX(0,MIN(AA13-AB13,$B13-(E13+I13+M13+Q13+U13+Y13))) -> 0 | AD13: =MAX(0,AA13-AB13-AC13) -> 0 | AE13: =IF(AH12>0.005,AH12*(1+Ordem!$E$13),0) -> 0 | AF13: =MIN(AE13,Ordem!$F$13) -> 0 | AG13: =MAX(0,MIN(AE13-AF13,$B13-(E13+I13+M13+Q13+U13+Y13+AC13))) -> 0 | AH13: =MAX(0,AE13-AF13-AG13) -> 0 | AI13: =IF(AL12>0.005,AL12*(1+Ordem!$E$14),0) -> 0 | AJ13: =MIN(AI13,Ordem!$F$14) -> 0 | AK13: =MAX(0,MIN(AI13-AJ13,$B13-(E13+I13+M13+Q13+U13+Y13+AC13+AG13))) -> 0 | AL13: =MAX(0,AI13-AJ13-AK13) -> 0 | AM13: =IF(AP12>0.005,AP12*(1+Ordem!$E$15),0) -> 0 | AN13: =MIN(AM13,Ordem!$F$15) -> 0 | AO13: =MAX(0,MIN(AM13-AN13,$B13-(E13+I13+M13+Q13+U13+Y13+AC13+AG13+AK13))) -> 0 | AP13: =MAX(0,AM13-AN13-AO13) -> 0 | AQ13: =F13+J13+N13+R13+V13+Z13+AD13+AH13+AL13+AP13 -> 4356.5055 | AR13: =D13+E13+H13+I13+L13+M13+P13+Q13+T13+U13+X13+Y13+AB13+AC13+AF13+AG13+AJ13+AK13+AN13+AO13 -> 1450
A14: 10 | B14: =MAX(0,Dívidas!$C$20-(D14+H14+L14+P14+T14+X14+AB14+AF14+AJ14+AN14)) -> 1000 | C14: =IF(F13>0.005,F13*(1+Ordem!$E$6),0) -> 0 | D14: =MIN(C14,Ordem!$F$6) -> 0 | E14: =MAX(0,MIN(C14-D14,$B14-(0))) -> 0 | F14: =MAX(0,C14-D14-E14) -> 0 | G14: =IF(J13>0.005,J13*(1+Ordem!$E$7),0) -> 0 | H14: =MIN(G14,Ordem!$F$7) -> 0 | I14: =MAX(0,MIN(G14-H14,$B14-(E14))) -> 0 | J14: =MAX(0,G14-H14-I14) -> 0 | K14: =IF(N13>0.005,N13*(1+Ordem!$E$8),0) -> 4508.9832 | L14: =MIN(K14,Ordem!$F$8) -> 450 | M14: =MAX(0,MIN(K14-L14,$B14-(E14+I14))) -> 1000 | N14: =MAX(0,K14-L14-M14) -> 3058.9832 | O14: =IF(R13>0.005,R13*(1+Ordem!$E$9),0) -> 0 | P14: =MIN(O14,Ordem!$F$9) -> 0 | Q14: =MAX(0,MIN(O14-P14,$B14-(E14+I14+M14))) -> 0 | R14: =MAX(0,O14-P14-Q14) -> 0 | S14: =IF(V13>0.005,V13*(1+Ordem!$E$10),0) -> 0 | T14: =MIN(S14,Ordem!$F$10) -> 0 | U14: =MAX(0,MIN(S14-T14,$B14-(E14+I14+M14+Q14))) -> 0 | V14: =MAX(0,S14-T14-U14) -> 0 | W14: =IF(Z13>0.005,Z13*(1+Ordem!$E$11),0) -> 0 | X14: =MIN(W14,Ordem!$F$11) -> 0 | Y14: =MAX(0,MIN(W14-X14,$B14-(E14+I14+M14+Q14+U14))) -> 0 | Z14: =MAX(0,W14-X14-Y14) -> 0 | AA14: =IF(AD13>0.005,AD13*(1+Ordem!$E$12),0) -> 0 | AB14: =MIN(AA14,Ordem!$F$12) -> 0 | AC14: =MAX(0,MIN(AA14-AB14,$B14-(E14+I14+M14+Q14+U14+Y14))) -> 0 | AD14: =MAX(0,AA14-AB14-AC14) -> 0 | AE14: =IF(AH13>0.005,AH13*(1+Ordem!$E$13),0) -> 0 | AF14: =MIN(AE14,Ordem!$F$13) -> 0 | AG14: =MAX(0,MIN(AE14-AF14,$B14-(E14+I14+M14+Q14+U14+Y14+AC14))) -> 0 | AH14: =MAX(0,AE14-AF14-AG14) -> 0 | AI14: =IF(AL13>0.005,AL13*(1+Ordem!$E$14),0) -> 0 | AJ14: =MIN(AI14,Ordem!$F$14) -> 0 | AK14: =MAX(0,MIN(AI14-AJ14,$B14-(E14+I14+M14+Q14+U14+Y14+AC14+AG14))) -> 0 | AL14: =MAX(0,AI14-AJ14-AK14) -> 0 | AM14: =IF(AP13>0.005,AP13*(1+Ordem!$E$15),0) -> 0 | AN14: =MIN(AM14,Ordem!$F$15) -> 0 | AO14: =MAX(0,MIN(AM14-AN14,$B14-(E14+I14+M14+Q14+U14+Y14+AC14+AG14+AK14))) -> 0 | AP14: =MAX(0,AM14-AN14-AO14) -> 0 | AQ14: =F14+J14+N14+R14+V14+Z14+AD14+AH14+AL14+AP14 -> 3058.9832 | AR14: =D14+E14+H14+I14+L14+M14+P14+Q14+T14+U14+X14+Y14+AB14+AC14+AF14+AG14+AJ14+AK14+AN14+AO14 -> 1450
A15: 11 | B15: =MAX(0,Dívidas!$C$20-(D15+H15+L15+P15+T15+X15+AB15+AF15+AJ15+AN15)) -> 1000 | C15: =IF(F14>0.005,F14*(1+Ordem!$E$6),0) -> 0 | D15: =MIN(C15,Ordem!$F$6) -> 0 | E15: =MAX(0,MIN(C15-D15,$B15-(0))) -> 0 | F15: =MAX(0,C15-D15-E15) -> 0 | G15: =IF(J14>0.005,J14*(1+Ordem!$E$7),0) -> 0 | H15: =MIN(G15,Ordem!$F$7) -> 0 | I15: =MAX(0,MIN(G15-H15,$B15-(E15))) -> 0 | J15: =MAX(0,G15-H15-I15) -> 0 | K15: =IF(N14>0.005,N14*(1+Ordem!$E$8),0) -> 3166.0476 | L15: =MIN(K15,Ordem!$F$8) -> 450 | M15: =MAX(0,MIN(K15-L15,$B15-(E15+I15))) -> 1000 | N15: =MAX(0,K15-L15-M15) -> 1716.0476 | O15: =IF(R14>0.005,R14*(1+Ordem!$E$9),0) -> 0 | P15: =MIN(O15,Ordem!$F$9) -> 0 | Q15: =MAX(0,MIN(O15-P15,$B15-(E15+I15+M15))) -> 0 | R15: =MAX(0,O15-P15-Q15) -> 0 | S15: =IF(V14>0.005,V14*(1+Ordem!$E$10),0) -> 0 | T15: =MIN(S15,Ordem!$F$10) -> 0 | U15: =MAX(0,MIN(S15-T15,$B15-(E15+I15+M15+Q15))) -> 0 | V15: =MAX(0,S15-T15-U15) -> 0 | W15: =IF(Z14>0.005,Z14*(1+Ordem!$E$11),0) -> 0 | X15: =MIN(W15,Ordem!$F$11) -> 0 | Y15: =MAX(0,MIN(W15-X15,$B15-(E15+I15+M15+Q15+U15))) -> 0 | Z15: =MAX(0,W15-X15-Y15) -> 0 | AA15: =IF(AD14>0.005,AD14*(1+Ordem!$E$12),0) -> 0 | AB15: =MIN(AA15,Ordem!$F$12) -> 0 | AC15: =MAX(0,MIN(AA15-AB15,$B15-(E15+I15+M15+Q15+U15+Y15))) -> 0 | AD15: =MAX(0,AA15-AB15-AC15) -> 0 | AE15: =IF(AH14>0.005,AH14*(1+Ordem!$E$13),0) -> 0 | AF15: =MIN(AE15,Ordem!$F$13) -> 0 | AG15: =MAX(0,MIN(AE15-AF15,$B15-(E15+I15+M15+Q15+U15+Y15+AC15))) -> 0 | AH15: =MAX(0,AE15-AF15-AG15) -> 0 | AI15: =IF(AL14>0.005,AL14*(1+Ordem!$E$14),0) -> 0 | AJ15: =MIN(AI15,Ordem!$F$14) -> 0 | AK15: =MAX(0,MIN(AI15-AJ15,$B15-(E15+I15+M15+Q15+U15+Y15+AC15+AG15))) -> 0 | AL15: =MAX(0,AI15-AJ15-AK15) -> 0 | AM15: =IF(AP14>0.005,AP14*(1+Ordem!$E$15),0) -> 0 | AN15: =MIN(AM15,Ordem!$F$15) -> 0 | AO15: =MAX(0,MIN(AM15-AN15,$B15-(E15+I15+M15+Q15+U15+Y15+AC15+AG15+AK15))) -> 0 | AP15: =MAX(0,AM15-AN15-AO15) -> 0 | AQ15: =F15+J15+N15+R15+V15+Z15+AD15+AH15+AL15+AP15 -> 1716.0476 | AR15: =D15+E15+H15+I15+L15+M15+P15+Q15+T15+U15+X15+Y15+AB15+AC15+AF15+AG15+AJ15+AK15+AN15+AO15 -> 1450
A16: 12 | B16: =MAX(0,Dívidas!$C$20-(D16+H16+L16+P16+T16+X16+AB16+AF16+AJ16+AN16)) -> 1000 | C16: =IF(F15>0.005,F15*(1+Ordem!$E$6),0) -> 0 | D16: =MIN(C16,Ordem!$F$6) -> 0 | E16: =MAX(0,MIN(C16-D16,$B16-(0))) -> 0 | F16: =MAX(0,C16-D16-E16) -> 0 | G16: =IF(J15>0.005,J15*(1+Ordem!$E$7),0) -> 0 | H16: =MIN(G16,Ordem!$F$7) -> 0 | I16: =MAX(0,MIN(G16-H16,$B16-(E16))) -> 0 | J16: =MAX(0,G16-H16-I16) -> 0 | K16: =IF(N15>0.005,N15*(1+Ordem!$E$8),0) -> 1776.1093 | L16: =MIN(K16,Ordem!$F$8) -> 450 | M16: =MAX(0,MIN(K16-L16,$B16-(E16+I16))) -> 1000 | N16: =MAX(0,K16-L16-M16) -> 326.10928 | O16: =IF(R15>0.005,R15*(1+Ordem!$E$9),0) -> 0 | P16: =MIN(O16,Ordem!$F$9) -> 0 | Q16: =MAX(0,MIN(O16-P16,$B16-(E16+I16+M16))) -> 0 | R16: =MAX(0,O16-P16-Q16) -> 0 | S16: =IF(V15>0.005,V15*(1+Ordem!$E$10),0) -> 0 | T16: =MIN(S16,Ordem!$F$10) -> 0 | U16: =MAX(0,MIN(S16-T16,$B16-(E16+I16+M16+Q16))) -> 0 | V16: =MAX(0,S16-T16-U16) -> 0 | W16: =IF(Z15>0.005,Z15*(1+Ordem!$E$11),0) -> 0 | X16: =MIN(W16,Ordem!$F$11) -> 0 | Y16: =MAX(0,MIN(W16-X16,$B16-(E16+I16+M16+Q16+U16))) -> 0 | Z16: =MAX(0,W16-X16-Y16) -> 0 | AA16: =IF(AD15>0.005,AD15*(1+Ordem!$E$12),0) -> 0 | AB16: =MIN(AA16,Ordem!$F$12) -> 0 | AC16: =MAX(0,MIN(AA16-AB16,$B16-(E16+I16+M16+Q16+U16+Y16))) -> 0 | AD16: =MAX(0,AA16-AB16-AC16) -> 0 | AE16: =IF(AH15>0.005,AH15*(1+Ordem!$E$13),0) -> 0 | AF16: =MIN(AE16,Ordem!$F$13) -> 0 | AG16: =MAX(0,MIN(AE16-AF16,$B16-(E16+I16+M16+Q16+U16+Y16+AC16))) -> 0 | AH16: =MAX(0,AE16-AF16-AG16) -> 0 | AI16: =IF(AL15>0.005,AL15*(1+Ordem!$E$14),0) -> 0 | AJ16: =MIN(AI16,Ordem!$F$14) -> 0 | AK16: =MAX(0,MIN(AI16-AJ16,$B16-(E16+I16+M16+Q16+U16+Y16+AC16+AG16))) -> 0 | AL16: =MAX(0,AI16-AJ16-AK16) -> 0 | AM16: =IF(AP15>0.005,AP15*(1+Ordem!$E$15),0) -> 0 | AN16: =MIN(AM16,Ordem!$F$15) -> 0 | AO16: =MAX(0,MIN(AM16-AN16,$B16-(E16+I16+M16+Q16+U16+Y16+AC16+AG16+AK16))) -> 0 | AP16: =MAX(0,AM16-AN16-AO16) -> 0 | AQ16: =F16+J16+N16+R16+V16+Z16+AD16+AH16+AL16+AP16 -> 326.10928 | AR16: =D16+E16+H16+I16+L16+M16+P16+Q16+T16+U16+X16+Y16+AB16+AC16+AF16+AG16+AJ16+AK16+AN16+AO16 -> 1450
A17: 13 | B17: =MAX(0,Dívidas!$C$20-(D17+H17+L17+P17+T17+X17+AB17+AF17+AJ17+AN17)) -> 1112.4769 | C17: =IF(F16>0.005,F16*(1+Ordem!$E$6),0) -> 0 | D17: =MIN(C17,Ordem!$F$6) -> 0 | E17: =MAX(0,MIN(C17-D17,$B17-(0))) -> 0 | F17: =MAX(0,C17-D17-E17) -> 0 | G17: =IF(J16>0.005,J16*(1+Ordem!$E$7),0) -> 0 | H17: =MIN(G17,Ordem!$F$7) -> 0 | I17: =MAX(0,MIN(G17-H17,$B17-(E17))) -> 0 | J17: =MAX(0,G17-H17-I17) -> 0 | K17: =IF(N16>0.005,N16*(1+Ordem!$E$8),0) -> 337.52311 | L17: =MIN(K17,Ordem!$F$8) -> 337.52311 | M17: =MAX(0,MIN(K17-L17,$B17-(E17+I17))) -> 0 | N17: =MAX(0,K17-L17-M17) -> 0 | O17: =IF(R16>0.005,R16*(1+Ordem!$E$9),0) -> 0 | P17: =MIN(O17,Ordem!$F$9) -> 0 | Q17: =MAX(0,MIN(O17-P17,$B17-(E17+I17+M17))) -> 0 | R17: =MAX(0,O17-P17-Q17) -> 0 | S17: =IF(V16>0.005,V16*(1+Ordem!$E$10),0) -> 0 | T17: =MIN(S17,Ordem!$F$10) -> 0 | U17: =MAX(0,MIN(S17-T17,$B17-(E17+I17+M17+Q17))) -> 0 | V17: =MAX(0,S17-T17-U17) -> 0 | W17: =IF(Z16>0.005,Z16*(1+Ordem!$E$11),0) -> 0 | X17: =MIN(W17,Ordem!$F$11) -> 0 | Y17: =MAX(0,MIN(W17-X17,$B17-(E17+I17+M17+Q17+U17))) -> 0 | Z17: =MAX(0,W17-X17-Y17) -> 0 | AA17: =IF(AD16>0.005,AD16*(1+Ordem!$E$12),0) -> 0 | AB17: =MIN(AA17,Ordem!$F$12) -> 0 | AC17: =MAX(0,MIN(AA17-AB17,$B17-(E17+I17+M17+Q17+U17+Y17))) -> 0 | AD17: =MAX(0,AA17-AB17-AC17) -> 0 | AE17: =IF(AH16>0.005,AH16*(1+Ordem!$E$13),0) -> 0 | AF17: =MIN(AE17,Ordem!$F$13) -> 0 | AG17: =MAX(0,MIN(AE17-AF17,$B17-(E17+I17+M17+Q17+U17+Y17+AC17))) -> 0 | AH17: =MAX(0,AE17-AF17-AG17) -> 0 | AI17: =IF(AL16>0.005,AL16*(1+Ordem!$E$14),0) -> 0 | AJ17: =MIN(AI17,Ordem!$F$14) -> 0 | AK17: =MAX(0,MIN(AI17-AJ17,$B17-(E17+I17+M17+Q17+U17+Y17+AC17+AG17))) -> 0 | AL17: =MAX(0,AI17-AJ17-AK17) -> 0 | AM17: =IF(AP16>0.005,AP16*(1+Ordem!$E$15),0) -> 0 | AN17: =MIN(AM17,Ordem!$F$15) -> 0 | AO17: =MAX(0,MIN(AM17-AN17,$B17-(E17+I17+M17+Q17+U17+Y17+AC17+AG17+AK17))) -> 0 | AP17: =MAX(0,AM17-AN17-AO17) -> 0 | AQ17: =F17+J17+N17+R17+V17+Z17+AD17+AH17+AL17+AP17 -> 0 | AR17: =D17+E17+H17+I17+L17+M17+P17+Q17+T17+U17+X17+Y17+AB17+AC17+AF17+AG17+AJ17+AK17+AN17+AO17 -> 337.52311
... A124: 120 | B124: =MAX(0,Dívidas!$C$20-(D124+H124+L124+P124+T124+X124+AB124+AF124+AJ124+AN124)) -> 1450 | C124: =IF(F123>0.005,F123*(1+Ordem!$E$6),0) -> 0 | D124: =MIN(C124,Ordem!$F$6) -> 0 | E124: =MAX(0,MIN(C124-D124,$B124-(0))) -> 0 | F124: =MAX(0,C124-D124-E124) -> 0 | G124: =IF(J123>0.005,J123*(1+Ordem!$E$7),0) -> 0 | H124: =MIN(G124,Ordem!$F$7) -> 0 | I124: =MAX(0,MIN(G124-H124,$B124-(E124))) -> 0 | J124: =MAX(0,G124-H124-I124) -> 0 | K124: =IF(N123>0.005,N123*(1+Ordem!$E$8),0) -> 0 | L124: =MIN(K124,Ordem!$F$8) -> 0 | M124: =MAX(0,MIN(K124-L124,$B124-(E124+I124))) -> 0 | N124: =MAX(0,K124-L124-M124) -> 0 | O124: =IF(R123>0.005,R123*(1+Ordem!$E$9),0) -> 0 | P124: =MIN(O124,Ordem!$F$9) -> 0 | Q124: =MAX(0,MIN(O124-P124,$B124-(E124+I124+M124))) -> 0 | R124: =MAX(0,O124-P124-Q124) -> 0 | S124: =IF(V123>0.005,V123*(1+Ordem!$E$10),0) -> 0 | T124: =MIN(S124,Ordem!$F$10) -> 0 | U124: =MAX(0,MIN(S124-T124,$B124-(E124+I124+M124+Q124))) -> 0 | V124: =MAX(0,S124-T124-U124) -> 0 | W124: =IF(Z123>0.005,Z123*(1+Ordem!$E$11),0) -> 0 | X124: =MIN(W124,Ordem!$F$11) -> 0 | Y124: =MAX(0,MIN(W124-X124,$B124-(E124+I124+M124+Q124+U124))) -> 0 | Z124: =MAX(0,W124-X124-Y124) -> 0 | AA124: =IF(AD123>0.005,AD123*(1+Ordem!$E$12),0) -> 0 | AB124: =MIN(AA124,Ordem!$F$12) -> 0 | AC124: =MAX(0,MIN(AA124-AB124,$B124-(E124+I124+M124+Q124+U124+Y124))) -> 0 | AD124: =MAX(0,AA124-AB124-AC124) -> 0 | AE124: =IF(AH123>0.005,AH123*(1+Ordem!$E$13),0) -> 0 | AF124: =MIN(AE124,Ordem!$F$13) -> 0 | AG124: =MAX(0,MIN(AE124-AF124,$B124-(E124+I124+M124+Q124+U124+Y124+AC124))) -> 0 | AH124: =MAX(0,AE124-AF124-AG124) -> 0 | AI124: =IF(AL123>0.005,AL123*(1+Ordem!$E$14),0) -> 0 | AJ124: =MIN(AI124,Ordem!$F$14) -> 0 | AK124: =MAX(0,MIN(AI124-AJ124,$B124-(E124+I124+M124+Q124+U124+Y124+AC124+AG124))) -> 0 | AL124: =MAX(0,AI124-AJ124-AK124) -> 0 | AM124: =IF(AP123>0.005,AP123*(1+Ordem!$E$15),0) -> 0 | AN124: =MIN(AM124,Ordem!$F$15) -> 0 | AO124: =MAX(0,MIN(AM124-AN124,$B124-(E124+I124+M124+Q124+U124+Y124+AC124+AG124+AK124))) -> 0 | AP124: =MAX(0,AM124-AN124-AO124) -> 0 | AQ124: =F124+J124+N124+R124+V124+Z124+AD124+AH124+AL124+AP124 -> 0 | AR124: =D124+E124+H124+I124+L124+M124+P124+Q124+T124+U124+X124+Y124+AB124+AC124+AF124+AG124+AJ124+AK124+AN124+AO124 -> 0

Sheet Sim Bola de neve
A1: Simulação mês a mês · Bola de neve
A2: Cálculo automático. Não precisa mexer aqui.
A4: Mês | B4: Sobra p/ extra | C4: 1ª · Devido | D4: 1ª · Mínima | E4: 1ª · Extra | F4: 1ª · Saldo | G4: 2ª · Devido | H4: 2ª · Mínima | I4: 2ª · Extra | J4: 2ª · Saldo | K4: 3ª · Devido | L4: 3ª · Mínima | M4: 3ª · Extra | N4: 3ª · Saldo | O4: 4ª · Devido | P4: 4ª · Mínima | Q4: 4ª · Extra | R4: 4ª · Saldo | S4: 5ª · Devido | T4: 5ª · Mínima | U4: 5ª · Extra | V4: 5ª · Saldo | W4: 6ª · Devido | X4: 6ª · Mínima | Y4: 6ª · Extra | Z4: 6ª · Saldo | AA4: 7ª · Devido | AB4: 7ª · Mínima | AC4: 7ª · Extra | AD4: 7ª · Saldo | AE4: 8ª · Devido | AF4: 8ª · Mínima | AG4: 8ª · Extra | AH4: 8ª · Saldo | AI4: 9ª · Devido | AJ4: 9ª · Mínima | AK4: 9ª · Extra | AL4: 9ª · Saldo | AM4: 10ª · Devido | AN4: 10ª · Mínima | AO4: 10ª · Extra | AP4: 10ª · Saldo | AQ4: Saldo total | AR4: Pago no mês
A5: 1 | B5: =MAX(0,Dívidas!$C$20-(D5+H5+L5+P5+T5+X5+AB5+AF5+AJ5+AN5)) -> 400 | C5: =IF(Ordem!$J$6>0.005,Ordem!$J$6*(1+Ordem!$K$6),0) -> 900 | D5: =MIN(C5,Ordem!$L$6) -> 150 | E5: =MAX(0,MIN(C5-D5,$B5-(0))) -> 400 | F5: =MAX(0,C5-D5-E5) -> 350 | G5: =IF(Ordem!$J$7>0.005,Ordem!$J$7*(1+Ordem!$K$7),0) -> 1296 | H5: =MIN(G5,Ordem!$L$7) -> 150 | I5: =MAX(0,MIN(G5-H5,$B5-(E5))) -> 0 | J5: =MAX(0,G5-H5-I5) -> 1146 | K5: =IF(Ordem!$J$8>0.005,Ordem!$J$8*(1+Ordem!$K$8),0) -> 3360 | L5: =MIN(K5,Ordem!$L$8) -> 300 | M5: =MAX(0,MIN(K5-L5,$B5-(E5+I5))) -> 0 | N5: =MAX(0,K5-L5-M5) -> 3060 | O5: =IF(Ordem!$J$9>0.005,Ordem!$J$9*(1+Ordem!$K$9),0) -> 8280 | P5: =MIN(O5,Ordem!$L$9) -> 450 | Q5: =MAX(0,MIN(O5-P5,$B5-(E5+I5+M5))) -> 0 | R5: =MAX(0,O5-P5-Q5) -> 7830 | S5: =IF(Ordem!$J$10>0.005,Ordem!$J$10*(1+Ordem!$K$10),0) -> 0 | T5: =MIN(S5,Ordem!$L$10) -> 0 | U5: =MAX(0,MIN(S5-T5,$B5-(E5+I5+M5+Q5))) -> 0 | V5: =MAX(0,S5-T5-U5) -> 0 | W5: =IF(Ordem!$J$11>0.005,Ordem!$J$11*(1+Ordem!$K$11),0) -> 0 | X5: =MIN(W5,Ordem!$L$11) -> 0 | Y5: =MAX(0,MIN(W5-X5,$B5-(E5+I5+M5+Q5+U5))) -> 0 | Z5: =MAX(0,W5-X5-Y5) -> 0 | AA5: =IF(Ordem!$J$12>0.005,Ordem!$J$12*(1+Ordem!$K$12),0) -> 0 | AB5: =MIN(AA5,Ordem!$L$12) -> 0 | AC5: =MAX(0,MIN(AA5-AB5,$B5-(E5+I5+M5+Q5+U5+Y5))) -> 0 | AD5: =MAX(0,AA5-AB5-AC5) -> 0 | AE5: =IF(Ordem!$J$13>0.005,Ordem!$J$13*(1+Ordem!$K$13),0) -> 0 | AF5: =MIN(AE5,Ordem!$L$13) -> 0 | AG5: =MAX(0,MIN(AE5-AF5,$B5-(E5+I5+M5+Q5+U5+Y5+AC5))) -> 0 | AH5: =MAX(0,AE5-AF5-AG5) -> 0 | AI5: =IF(Ordem!$J$14>0.005,Ordem!$J$14*(1+Ordem!$K$14),0) -> 0 | AJ5: =MIN(AI5,Ordem!$L$14) -> 0 | AK5: =MAX(0,MIN(AI5-AJ5,$B5-(E5+I5+M5+Q5+U5+Y5+AC5+AG5))) -> 0 | AL5: =MAX(0,AI5-AJ5-AK5) -> 0 | AM5: =IF(Ordem!$J$15>0.005,Ordem!$J$15*(1+Ordem!$K$15),0) -> 0 | AN5: =MIN(AM5,Ordem!$L$15) -> 0 | AO5: =MAX(0,MIN(AM5-AN5,$B5-(E5+I5+M5+Q5+U5+Y5+AC5+AG5+AK5))) -> 0 | AP5: =MAX(0,AM5-AN5-AO5) -> 0 | AQ5: =F5+J5+N5+R5+V5+Z5+AD5+AH5+AL5+AP5 -> 12386 | AR5: =D5+E5+H5+I5+L5+M5+P5+Q5+T5+U5+X5+Y5+AB5+AC5+AF5+AG5+AJ5+AK5+AN5+AO5 -> 1450
A6: 2 | B6: =MAX(0,Dívidas!$C$20-(D6+H6+L6+P6+T6+X6+AB6+AF6+AJ6+AN6)) -> 400 | C6: =IF(F5>0.005,F5*(1+Ordem!$K$6),0) -> 350 | D6: =MIN(C6,Ordem!$L$6) -> 150 | E6: =MAX(0,MIN(C6-D6,$B6-(0))) -> 200 | F6: =MAX(0,C6-D6-E6) -> 0 | G6: =IF(J5>0.005,J5*(1+Ordem!$K$7),0) -> 1237.68 | H6: =MIN(G6,Ordem!$L$7) -> 150 | I6: =MAX(0,MIN(G6-H6,$B6-(E6))) -> 200 | J6: =MAX(0,G6-H6-I6) -> 887.68 | K6: =IF(N5>0.005,N5*(1+Ordem!$K$8),0) -> 3427.2 | L6: =MIN(K6,Ordem!$L$8) -> 300 | M6: =MAX(0,MIN(K6-L6,$B6-(E6+I6))) -> 0 | N6: =MAX(0,K6-L6-M6) -> 3127.2 | O6: =IF(R5>0.005,R5*(1+Ordem!$K$9),0) -> 8104.05 | P6: =MIN(O6,Ordem!$L$9) -> 450 | Q6: =MAX(0,MIN(O6-P6,$B6-(E6+I6+M6))) -> 0 | R6: =MAX(0,O6-P6-Q6) -> 7654.05 | S6: =IF(V5>0.005,V5*(1+Ordem!$K$10),0) -> 0 | T6: =MIN(S6,Ordem!$L$10) -> 0 | U6: =MAX(0,MIN(S6-T6,$B6-(E6+I6+M6+Q6))) -> 0 | V6: =MAX(0,S6-T6-U6) -> 0 | W6: =IF(Z5>0.005,Z5*(1+Ordem!$K$11),0) -> 0 | X6: =MIN(W6,Ordem!$L$11) -> 0 | Y6: =MAX(0,MIN(W6-X6,$B6-(E6+I6+M6+Q6+U6))) -> 0 | Z6: =MAX(0,W6-X6-Y6) -> 0 | AA6: =IF(AD5>0.005,AD5*(1+Ordem!$K$12),0) -> 0 | AB6: =MIN(AA6,Ordem!$L$12) -> 0 | AC6: =MAX(0,MIN(AA6-AB6,$B6-(E6+I6+M6+Q6+U6+Y6))) -> 0 | AD6: =MAX(0,AA6-AB6-AC6) -> 0 | AE6: =IF(AH5>0.005,AH5*(1+Ordem!$K$13),0) -> 0 | AF6: =MIN(AE6,Ordem!$L$13) -> 0 | AG6: =MAX(0,MIN(AE6-AF6,$B6-(E6+I6+M6+Q6+U6+Y6+AC6))) -> 0 | AH6: =MAX(0,AE6-AF6-AG6) -> 0 | AI6: =IF(AL5>0.005,AL5*(1+Ordem!$K$14),0) -> 0 | AJ6: =MIN(AI6,Ordem!$L$14) -> 0 | AK6: =MAX(0,MIN(AI6-AJ6,$B6-(E6+I6+M6+Q6+U6+Y6+AC6+AG6))) -> 0 | AL6: =MAX(0,AI6-AJ6-AK6) -> 0 | AM6: =IF(AP5>0.005,AP5*(1+Ordem!$K$15),0) -> 0 | AN6: =MIN(AM6,Ordem!$L$15) -> 0 | AO6: =MAX(0,MIN(AM6-AN6,$B6-(E6+I6+M6+Q6+U6+Y6+AC6+AG6+AK6))) -> 0 | AP6: =MAX(0,AM6-AN6-AO6) -> 0 | AQ6: =F6+J6+N6+R6+V6+Z6+AD6+AH6+AL6+AP6 -> 11668.93 | AR6: =D6+E6+H6+I6+L6+M6+P6+Q6+T6+U6+X6+Y6+AB6+AC6+AF6+AG6+AJ6+AK6+AN6+AO6 -> 1450
A7: 3 | B7: =MAX(0,Dívidas!$C$20-(D7+H7+L7+P7+T7+X7+AB7+AF7+AJ7+AN7)) -> 550 | C7: =IF(F6>0.005,F6*(1+Ordem!$K$6),0) -> 0 | D7: =MIN(C7,Ordem!$L$6) -> 0 | E7: =MAX(0,MIN(C7-D7,$B7-(0))) -> 0 | F7: =MAX(0,C7-D7-E7) -> 0 | G7: =IF(J6>0.005,J6*(1+Ordem!$K$7),0) -> 958.6944 | H7: =MIN(G7,Ordem!$L$7) -> 150 | I7: =MAX(0,MIN(G7-H7,$B7-(E7))) -> 550 | J7: =MAX(0,G7-H7-I7) -> 258.6944 | K7: =IF(N6>0.005,N6*(1+Ordem!$K$8),0) -> 3502.464 | L7: =MIN(K7,Ordem!$L$8) -> 300 | M7: =MAX(0,MIN(K7-L7,$B7-(E7+I7))) -> 0 | N7: =MAX(0,K7-L7-M7) -> 3202.464 | O7: =IF(R6>0.005,R6*(1+Ordem!$K$9),0) -> 7921.9417 | P7: =MIN(O7,Ordem!$L$9) -> 450 | Q7: =MAX(0,MIN(O7-P7,$B7-(E7+I7+M7))) -> 0 | R7: =MAX(0,O7-P7-Q7) -> 7471.9417 | S7: =IF(V6>0.005,V6*(1+Ordem!$K$10),0) -> 0 | T7: =MIN(S7,Ordem!$L$10) -> 0 | U7: =MAX(0,MIN(S7-T7,$B7-(E7+I7+M7+Q7))) -> 0 | V7: =MAX(0,S7-T7-U7) -> 0 | W7: =IF(Z6>0.005,Z6*(1+Ordem!$K$11),0) -> 0 | X7: =MIN(W7,Ordem!$L$11) -> 0 | Y7: =MAX(0,MIN(W7-X7,$B7-(E7+I7+M7+Q7+U7))) -> 0 | Z7: =MAX(0,W7-X7-Y7) -> 0 | AA7: =IF(AD6>0.005,AD6*(1+Ordem!$K$12),0) -> 0 | AB7: =MIN(AA7,Ordem!$L$12) -> 0 | AC7: =MAX(0,MIN(AA7-AB7,$B7-(E7+I7+M7+Q7+U7+Y7))) -> 0 | AD7: =MAX(0,AA7-AB7-AC7) -> 0 | AE7: =IF(AH6>0.005,AH6*(1+Ordem!$K$13),0) -> 0 | AF7: =MIN(AE7,Ordem!$L$13) -> 0 | AG7: =MAX(0,MIN(AE7-AF7,$B7-(E7+I7+M7+Q7+U7+Y7+AC7))) -> 0 | AH7: =MAX(0,AE7-AF7-AG7) -> 0 | AI7: =IF(AL6>0.005,AL6*(1+Ordem!$K$14),0) -> 0 | AJ7: =MIN(AI7,Ordem!$L$14) -> 0 | AK7: =MAX(0,MIN(AI7-AJ7,$B7-(E7+I7+M7+Q7+U7+Y7+AC7+AG7))) -> 0 | AL7: =MAX(0,AI7-AJ7-AK7) -> 0 | AM7: =IF(AP6>0.005,AP6*(1+Ordem!$K$15),0) -> 0 | AN7: =MIN(AM7,Ordem!$L$15) -> 0 | AO7: =MAX(0,MIN(AM7-AN7,$B7-(E7+I7+M7+Q7+U7+Y7+AC7+AG7+AK7))) -> 0 | AP7: =MAX(0,AM7-AN7-AO7) -> 0 | AQ7: =F7+J7+N7+R7+V7+Z7+AD7+AH7+AL7+AP7 -> 10933.1 | AR7: =D7+E7+H7+I7+L7+M7+P7+Q7+T7+U7+X7+Y7+AB7+AC7+AF7+AG7+AJ7+AK7+AN7+AO7 -> 1450
A8: 4 | B8: =MAX(0,Dívidas!$C$20-(D8+H8+L8+P8+T8+X8+AB8+AF8+AJ8+AN8)) -> 550 | C8: =IF(F7>0.005,F7*(1+Ordem!$K$6),0) -> 0 | D8: =MIN(C8,Ordem!$L$6) -> 0 | E8: =MAX(0,MIN(C8-D8,$B8-(0))) -> 0 | F8: =MAX(0,C8-D8-E8) -> 0 | G8: =IF(J7>0.005,J7*(1+Ordem!$K$7),0) -> 279.38995 | H8: =MIN(G8,Ordem!$L$7) -> 150 | I8: =MAX(0,MIN(G8-H8,$B8-(E8))) -> 129.38995 | J8: =MAX(0,G8-H8-I8) -> 0 | K8: =IF(N7>0.005,N7*(1+Ordem!$K$8),0) -> 3586.7597 | L8: =MIN(K8,Ordem!$L$8) -> 300 | M8: =MAX(0,MIN(K8-L8,$B8-(E8+I8))) -> 420.61005 | N8: =MAX(0,K8-L8-M8) -> 2866.1496 | O8: =IF(R7>0.005,R7*(1+Ordem!$K$9),0) -> 7733.4597 | P8: =MIN(O8,Ordem!$L$9) -> 450 | Q8: =MAX(0,MIN(O8-P8,$B8-(E8+I8+M8))) -> 0 | R8: =MAX(0,O8-P8-Q8) -> 7283.4597 | S8: =IF(V7>0.005,V7*(1+Ordem!$K$10),0) -> 0 | T8: =MIN(S8,Ordem!$L$10) -> 0 | U8: =MAX(0,MIN(S8-T8,$B8-(E8+I8+M8+Q8))) -> 0 | V8: =MAX(0,S8-T8-U8) -> 0 | W8: =IF(Z7>0.005,Z7*(1+Ordem!$K$11),0) -> 0 | X8: =MIN(W8,Ordem!$L$11) -> 0 | Y8: =MAX(0,MIN(W8-X8,$B8-(E8+I8+M8+Q8+U8))) -> 0 | Z8: =MAX(0,W8-X8-Y8) -> 0 | AA8: =IF(AD7>0.005,AD7*(1+Ordem!$K$12),0) -> 0 | AB8: =MIN(AA8,Ordem!$L$12) -> 0 | AC8: =MAX(0,MIN(AA8-AB8,$B8-(E8+I8+M8+Q8+U8+Y8))) -> 0 | AD8: =MAX(0,AA8-AB8-AC8) -> 0 | AE8: =IF(AH7>0.005,AH7*(1+Ordem!$K$13),0) -> 0 | AF8: =MIN(AE8,Ordem!$L$13) -> 0 | AG8: =MAX(0,MIN(AE8-AF8,$B8-(E8+I8+M8+Q8+U8+Y8+AC8))) -> 0 | AH8: =MAX(0,AE8-AF8-AG8) -> 0 | AI8: =IF(AL7>0.005,AL7*(1+Ordem!$K$14),0) -> 0 | AJ8: =MIN(AI8,Ordem!$L$14) -> 0 | AK8: =MAX(0,MIN(AI8-AJ8,$B8-(E8+I8+M8+Q8+U8+Y8+AC8+AG8))) -> 0 | AL8: =MAX(0,AI8-AJ8-AK8) -> 0 | AM8: =IF(AP7>0.005,AP7*(1+Ordem!$K$15),0) -> 0 | AN8: =MIN(AM8,Ordem!$L$15) -> 0 | AO8: =MAX(0,MIN(AM8-AN8,$B8-(E8+I8+M8+Q8+U8+Y8+AC8+AG8+AK8))) -> 0 | AP8: =MAX(0,AM8-AN8-AO8) -> 0 | AQ8: =F8+J8+N8+R8+V8+Z8+AD8+AH8+AL8+AP8 -> 10149.609 | AR8: =D8+E8+H8+I8+L8+M8+P8+Q8+T8+U8+X8+Y8+AB8+AC8+AF8+AG8+AJ8+AK8+AN8+AO8 -> 1450
